Workbook

Sheet Identificação
A1: CHAVE | B1: NUM | C1: TIPO | D1: CODESTA | E1: ESTADO | F1: MUNICIPIO | G1: CODMUN | H1: CNES | I1: CODCNES | J1: NOME | K1: CHAVE | L1: GENER | M1: TEAP | N1: REGIME | O1: GESTAO | P1: confere_sala | Q1: confere_MGMDP | R1: confere_STIC | S1: confere_DSA | T1: confere_DIN | U1: confere_DTS | V1: confere_DTP
A2: 0169MO31310620002 | B2: 0169 | C2: MO | D2: 31 | E2: Minas Gerais | F2: Belo Horizonte | G2: 3106200 | H2: 0 | J2: Unidade Gestora de Monitoração Eletrônica de Belo Horizonte I - DOMICILIAR | K2: 0169MO31310620002 | L2: 2 | M2: 0 | N2: 2 | O2: 0 | P2: =VLOOKUP(A2,'[1]2019'!$A$1:$C$22,3,0) -> Unidade Gestora de Monitoração Eletrônica de Belo Horizonte I - DOMICILIAR | Q2: =VLOOKUP(A2,'[2]2019'!$A$2:$B$24,2,0) -> Unidade Gestora de Monitoração Eletrônica de Belo Horizonte I - DOMICILIAR | R2: =VLOOKUP(A2,'[3]2019'!$A$2:$B$24,2,0) -> Unidade Gestora de Monitoração Eletrônica de Belo Horizonte I - DOMICILIAR | S2: =VLOOKUP(A2,'[4]2019'!$A$2:$B$24,2,0) -> Unidade Gestora de Monitoração Eletrônica de Belo Horizonte I - DOMICILIAR | T2: =VLOOKUP(A2,'[5]2019'!$A$2:$B$24,2,0) -> Unidade Gestora de Monitoração Eletrônica de Belo Horizonte I - DOMICILIAR | U2: =VLOOKUP(A2,'[6]2019'!$A$1:$B$24,2,0) -> Unidade Gestora de Monitoração Eletrônica de Belo Horizonte I - DOMICILIAR | V2: =VLOOKUP(A2,'[7]2019'!$A$2:$B$24,2,0) -> Unidade Gestora de Monitoração Eletrônica de Belo Horizonte I - DOMICILIAR
A3: 0170EF31310620011 | B3: 0170 | C3: EF | D3: 31 | E3: Minas Gerais | F3: Belo Horizonte | G3: 3106200 | H3: 1 | I3: 3329917 | J3: Penitenciária de Belo Horizonte I - Estevão Pinto | K3: 0170EF31310620011 | L3: 1 | M3: 74 | N3: 0 | O3: 0 | P3: =VLOOKUP(A3,'[1]2019'!$A$1:$C$22,3,0) -> Penitenciária de Belo Horizonte I - Estevão Pinto | Q3: =VLOOKUP(A3,'[2]2019'!$A$2:$B$24,2,0) -> Penitenciária de Belo Horizonte I - Estevão Pinto | R3: =VLOOKUP(A3,'[3]2019'!$A$2:$B$24,2,0) -> Penitenciária de Belo Horizonte I - Estevão Pinto | S3: =VLOOKUP(A3,'[4]2019'!$A$2:$B$24,2,0) -> Penitenciária de Belo Horizonte I - Estevão Pinto | T3: =VLOOKUP(A3,'[5]2019'!$A$2:$B$24,2,0) -> Penitenciária de Belo Horizonte I - Estevão Pinto | U3: =VLOOKUP(A3,'[6]2019'!$A$1:$B$24,2,0) -> Penitenciária de Belo Horizonte I - Estevão Pinto | V3: =VLOOKUP(A3,'[7]2019'!$A$2:$B$24,2,0) -> Penitenciária de Belo Horizonte I - Estevão Pinto
A4: 0171EF31311430300 | B4: 0171 | C4: EF | D4: 31 | E4: Minas Gerais | F4: Carmo do Paranaíba | G4: 3114303 | H4: 0 | J4: Penitenciária de Carmo do Parnaíba I | K4: 0171EF31311430300 | L4: 0 | M4: 0 | N4: 0 | O4: 0 | P4: =VLOOKUP(A4,'[1]2019'!$A$1:$C$22,3,0) -> Penitenciária de Carmo do Parnaíba I | Q4: =VLOOKUP(A4,'[2]2019'!$A$2:$B$24,2,0) -> Penitenciária de Carmo do Parnaíba I | R4: =VLOOKUP(A4,'[3]2019'!$A$2:$B$24,2,0) -> Penitenciária de Carmo do Parnaíba I | S4: =VLOOKUP(A4,'[4]2019'!$A$2:$B$24,2,0) -> Penitenciária de Carmo do Parnaíba I | T4: =VLOOKUP(A4,'[5]2019'!$A$2:$B$24,2,0) -> Penitenciária de Carmo do Paranaíba I | U4: =VLOOKUP(A4,'[6]2019'!$A$1:$B$24,2,0) -> Penitenciária de Carmo do Parnaíba I | V4: =VLOOKUP(A4,'[7]2019'!$A$2:$B$24,2,0) -> Penitenciária de Carmo do Parnaíba I
A5: 0172EF31311860112 | B5: 0172 | C5: EF | D5: 31 | E5: Minas Gerais | F5: Contagem | G5: 3118601 | H5: 1 | I5: 3214540 | J5: Penitenciária de Contagem I - Nelson Hungria | K5: 0172EF31311860112 | L5: 2 | M5: 74 | N5: 0 | O5: 0 | P5: =VLOOKUP(A5,'[1]2019'!$A$1:$C$22,3,0) -> Penitenciária de Contagem I - Nelson Hungria | Q5: =VLOOKUP(A5,'[2]2019'!$A$2:$B$24,2,0) -> Penitenciária de Contagem I - Nelson Hungria | R5: =VLOOKUP(A5,'[3]2019'!$A$2:$B$24,2,0) -> Penitenciária de Contagem I - Nelson Hungria | S5: =VLOOKUP(A5,'[4]2019'!$A$2:$B$24,2,0) -> Penitenciária de Contagem I - Nelson Hungria | T5: =VLOOKUP(A5,'[5]2019'!$A$2:$B$24,2,0) -> Penitenciária de Contagem I - Nelson Hungria | U5: =VLOOKUP(A5,'[6]2019'!$A$1:$B$24,2,0) -> Penitenciária de Contagem I - Nelson Hungria | V5: =VLOOKUP(A5,'[7]2019'!$A$2:$B$24,2,0) -> Penitenciária de Contagem I - Nelson Hungria
A6: 0173EF31312610910 | B6: 0173 | C6: EF | D6: 31 | E6: Minas Gerais | F6: Formiga | G6: 3126109 | H6: 1 | I6: 5984955 | J6: Penitenciária de Formiga I | K6: 0173EF31312610910 | L6: 0 | M6: 74 | N6: 0 | O6: 0 | P6: =VLOOKUP(A6,'[1]2019'!$A$1:$C$22,3,0) -> Penitenciária de Formiga I | Q6: =VLOOKUP(A6,'[2]2019'!$A$2:$B$24,2,0) -> Penitenciária de Formiga I | R6: =VLOOKUP(A6,'[3]2019'!$A$2:$B$24,2,0) -> Penitenciária de Formiga I | S6: =VLOOKUP(A6,'[4]2019'!$A$2:$B$24,2,0) -> Penitenciária de Formiga I | T6: =VLOOKUP(A6,'[5]2019'!$A$2:$B$24,2,0) -> Penitenciária de Formiga I | U6: =VLOOKUP(A6,'[6]2019'!$A$1:$B$24,2,0) -> Penitenciária de Formiga I | V6: =VLOOKUP(A6,'[7]2019'!$A$2:$B$24,2,0) -> Penitenciária de Formiga I
A7: 0174EF31312770100 | B7: 0174 | C7: EF | D7: 31 | E7: Minas Gerais | F7: Governador Valadares | G7: 3127701 | H7: 0 | J7: Penitenciária de Governador Valadares I - Francisco Floriano de Paula | K7: 0174EF31312770100 | L7: 0 | M7: 0 | N7: 0 | O7: 0 | P7: =VLOOKUP(A7,'[1]2019'!$A$1:$C$22,3,0) -> Penitenciária de Governador Valadares I - Francisco Floriano de Paula | Q7: =VLOOKUP(A7,'[2]2019'!$A$2:$B$24,2,0) -> Penitenciária de Governador Valadares I - Francisco Floriano de Paula | R7: =VLOOKUP(A7,'[3]2019'!$A$2:$B$24,2,0) -> Penitenciária de Governador Valadares I - Francisco Floriano de Paula | S7: =VLOOKUP(A7,'[4]2019'!$A$2:$B$24,2,0) -> Penitenciária de Governador Valadares I - Francisco Floriano de Paula | T7: =VLOOKUP(A7,'[5]2019'!$A$2:$B$24,2,0) -> Penitenciária de Governador Valadares I - Francisco Floriano de Paula | U7: =VLOOKUP(A7,'[6]2019'!$A$1:$B$24,2,0) -> Penitenciária de Governador Valadares I - Francisco Floriano de Paula | V7: =VLOOKUP(A7,'[7]2019'!$A$2:$B$24,2,0) -> Penitenciária de Governador Valadares I - Francisco Floriano de Paula
A8: 0175EF31313115800 | B8: 0175 | C8: EF | D8: 31 | E8: Minas Gerais | F8: Ipaba | G8: 3131158 | H8: 0 | J8: Penitenciária de Ipaba I - Dênio Moreira de Carvalho | K8: 0175EF31313115800 | L8: 0 | M8: 0 | N8: 0 | O8: 0 | P8: =VLOOKUP(A8,'[1]2019'!$A$1:$C$22,3,0) -> Penitenciária de Ipaba I - Dênio Moreira de Carvalho | Q8: =VLOOKUP(A8,'[2]2019'!$A$2:$B$24,2,0) -> Penitenciária de Ipaba I - Dênio Moreira de Carvalho | R8: =VLOOKUP(A8,'[3]2019'!$A$2:$B$24,2,0) -> Penitenciária de Ipaba I - Dênio Moreira de Carvalho | S8: =VLOOKUP(A8,'[4]2019'!$A$2:$B$24,2,0) -> Penitenciária de Ipaba I - Dênio Moreira de Carvalho | T8: =VLOOKUP(A8,'[5]2019'!$A$2:$B$24,2,0) -> Penitenciária de Ipaba I - Dênio Moreira de Carvalho | U8: =VLOOKUP(A8,'[6]2019'!$A$1:$B$24,2,0) -> Penitenciária de Ipaba I - Dênio Moreira de Carvalho | V8: =VLOOKUP(A8,'[7]2019'!$A$2:$B$24,2,0) -> Penitenciária de Ipaba I - Dênio Moreira de Carvalho
A9: 0176EF31313670212 | B9: 0176 | C9: EF | D9: 31 | E9: Minas Gerais | F9: Juiz de Fora | G9: 3136702 | H9: 1 | I9: 3573397 | J9: Penitenciária de Juiz de Fora I - José Edson Cavalieri | K9: 0176EF31313670212 | L9: 2 | M9: 0 | N9: 0 | O9: 0 | P9: =VLOOKUP(A9,'[1]2019'!$A$1:$C$22,3,0) -> Penitenciária de Juiz de Fora I - José Edson Cavalieri | Q9: =VLOOKUP(A9,'[2]2019'!$A$2:$B$24,2,0) -> Penitenciária de Juiz de Fora I - José Edson Cavalieri | R9: =VLOOKUP(A9,'[3]2019'!$A$2:$B$24,2,0) -> Penitenciária de Juiz de Fora I - José Edson Cavalieri | S9: =VLOOKUP(A9,'[4]2019'!$A$2:$B$24,2,0) -> Penitenciária de Juiz de Fora I - José Edson Cavalieri | T9: =VLOOKUP(A9,'[5]2019'!$A$2:$B$24,2,0) -> Penitenciária de Juiz de Fora I - José Edson Cavalieri | U9: =VLOOKUP(A9,'[6]2019'!$A$1:$B$24,2,0) -> Penitenciária de Juiz de Fora I - José Edson Cavalieri | V9: =VLOOKUP(A9,'[7]2019'!$A$2:$B$24,2,0) -> Penitenciária de Juiz de Fora I - José Edson Cavalieri
A10: 0177EF31313670202 | B10: 0177 | C10: EF | D10: 31 | E10: Minas Gerais | F10: Juiz de Fora | G10: 3136702 | H10: 0 | J10: Penitenciária de Juiz de Fora II | K10: 0177EF31313670202 | L10: 2 | M10: 74 | N10: 0 | O10: 0 | P10: =VLOOKUP(A10,'[1]2019'!$A$1:$C$22,3,0) -> Penitenciária de Juiz de Fora II | Q10: =VLOOKUP(A10,'[2]2019'!$A$2:$B$24,2,0) -> Penitenciária de Juiz de Fora II | R10: =VLOOKUP(A10,'[3]2019'!$A$2:$B$24,2,0) -> Penitenciária de Juiz de Fora II | S10: =VLOOKUP(A10,'[4]2019'!$A$2:$B$24,2,0) -> Penitenciária de Juiz de Fora II | T10: =VLOOKUP(A10,'[5]2019'!$A$2:$B$24,2,0) -> Penitenciária de Juiz de Fora II | U10: =VLOOKUP(A10,'[6]2019'!$A$1:$B$24,2,0) -> Penitenciária de Juiz de Fora II - Ariosvaldo | V10: =VLOOKUP(A10,'[7]2019'!$A$2:$B$24,2,0) -> Penitenciária de Juiz de Fora II
A11: 0178EF31314390610 | B11: 0178 | C11: EF | D11: 31 | E11: Minas Gerais | F11: Muriaé | G11: 3143906 | H11: 1 | I11: 5432588 | J11: Penitenciária de Muriaé I | K11: 0178EF31314390610 | L11: 0 | M11: 74 | N11: 0 | O11: 0 | P11: =VLOOKUP(A11,'[1]2019'!$A$1:$C$22,3,0) -> Penitenciária de Muriaé I | Q11: =VLOOKUP(A11,'[2]2019'!$A$2:$B$24,2,0) -> Penitenciária de Muriaé I | R11: =VLOOKUP(A11,'[3]2019'!$A$2:$B$24,2,0) -> Penitenciária de Muriaé I | S11: =VLOOKUP(A11,'[4]2019'!$A$2:$B$24,2,0) -> Penitenciária de Muriaé I | T11: =VLOOKUP(A11,'[5]2019'!$A$2:$B$24,2,0) -> Penitenciária de Muriaé I | U11: =VLOOKUP(A11,'[6]2019'!$A$1:$B$24,2,0) -> Penitenciária de Muriaé I - doutor martins | V11: =VLOOKUP(A11,'[7]2019'!$A$2:$B$24,2,0) -> Penitenciária de Muriaé I
A12: 0179EF31314710512 | B12: 0179 | C12: EF | D12: 31 | E12: Minas Gerais | F12: Pará de Minas | G12: 3147105 | H12: 1 | I12: 5809274 | J12: Penitenciária de Pará de Minas I - Doutor Pio Soares Canedo | K12: 0179EF31314710512 | L12: 2 | M12: 74 | N12: 0 | O12: 0 | P12: =VLOOKUP(A12,'[1]2019'!$A$1:$C$22,3,0) -> Penitenciária de Pará de Minas I - Doutor Pio Soares Canedo | Q12: =VLOOKUP(A12,'[2]2019'!$A$2:$B$24,2,0) -> Penitenciária de Pará de Minas I - Doutor Pio Soares Canedo | R12: =VLOOKUP(A12,'[3]2019'!$A$2:$B$24,2,0) -> Penitenciária de Pará de Minas I - Doutor Pio Soares Canedo | S12: =VLOOKUP(A12,'[4]2019'!$A$2:$B$24,2,0) -> Penitenciária de Pará de Minas I - Doutor Pio Soares Canedo | T12: =VLOOKUP(A12,'[5]2019'!$A$2:$B$24,2,0) -> Penitenciária de Pará de Minas I - Doutor Pio Soares Canedo | U12: =VLOOKUP(A12,'[6]2019'!$A$1:$B$24,2,0) -> Penitenciária de Pará de Minas I - Doutor Pio Soares Canedo | V12: =VLOOKUP(A12,'[7]2019'!$A$2:$B$24,2,0) -> Penitenciária de Pará de Minas I - Doutor Pio Soares Canedo
A13: 0180EF31314810310 | B13: 0180 | C13: EF | D13: 31 | E13: Minas Gerais | F13: Patrocínio | G13: 3148103 | H13: 1 | I13: 6828035 | J13: Penitenciária de Patrocínio I | K13: 0180EF31314810310 | L13: 0 | M13: 74 | N13: 0 | O13: 0 | P13: =VLOOKUP(A13,'[1]2019'!$A$1:$C$22,3,0) -> Penitenciária de Patrocínio I | Q13: =VLOOKUP(A13,'[2]2019'!$A$2:$B$24,2,0) -> Penitenciária de Patrocínio I | R13: =VLOOKUP(A13,'[3]2019'!$A$2:$B$24,2,0) -> Penitenciária de Patrocínio I | S13: =VLOOKUP(A13,'[4]2019'!$A$2:$B$24,2,0) -> Penitenciária de Patrocínio I | T13: =VLOOKUP(A13,'[5]2019'!$A$2:$B$24,2,0) -> Penitenciária de Patrocínio I | U13: =VLOOKUP(A13,'[6]2019'!$A$1:$B$24,2,0) -> Penitenciária de Patrocínio I - dep. Expedito | V13: =VLOOKUP(A13,'[7]2019'!$A$2:$B$24,2,0) -> Penitenciária de Patrocínio I
A14: 0181EF31315210510 | B14: 0181 | C14: EF | D14: 31 | E14: Minas Gerais | F14: Ponte Nova | G14: 3152105 | H14: 1 | I14: 7421842 | J14: Penitenciária de Ponte Nova I | K14: 0181EF31315210510 | L14: 0 | M14: 74 | N14: 0 | O14: 0 | P14: =VLOOKUP(A14,'[1]2019'!$A$1:$C$22,3,0) -> Penitenciária de Ponte Nova I | Q14: =VLOOKUP(A14,'[2]2019'!$A$2:$B$24,2,0) -> Penitenciária de Ponte Nova I | R14: =VLOOKUP(A14,'[3]2019'!$A$2:$B$24,2,0) -> Penitenciária de Ponte Nova I | S14: =VLOOKUP(A14,'[4]2019'!$A$2:$B$24,2,0) -> Penitenciária de Ponte Nova I | T14: =VLOOKUP(A14,'[5]2019'!$A$2:$B$24,2,0) -> Penitenciária de Ponte Nova I | U14: =VLOOKUP(A14,'[6]2019'!$A$1:$B$24,2,0) -> Penitenciária de Ponte Nova I - complexo penit | V14: =VLOOKUP(A14,'[7]2019'!$A$2:$B$24,2,0) -> Penitenciária de Ponte Nova I
A15: 0182EF31315460612 | B15: 0182 | C15: EF | D15: 31 | E15: Minas Gerais | F15: Ribeirão das Neves | G15: 3154606 | H15: 1 | I15: 2125765 | J15: Penitenciária de Ribeirão das Neves I - José Maria Alkimin | K15: 0182EF31315460612 | L15: 2 | M15: 74 | N15: 0 | O15: 0 | P15: =VLOOKUP(A15,'[1]2019'!$A$1:$C$22,3,0) -> Penitenciária de Ribeirão das Neves I - José Maria Alkimin | Q15: =VLOOKUP(A15,'[2]2019'!$A$2:$B$24,2,0) -> Penitenciária de Ribeirão das Neves I - José Maria Alkimin | R15: =VLOOKUP(A15,'[3]2019'!$A$2:$B$24,2,0) -> Penitenciária de Ribeirão das Neves I - José Maria Alkimin | S15: =VLOOKUP(A15,'[4]2019'!$A$2:$B$24,2,0) -> Penitenciária de Ribeirão das Neves I - José Maria Alkimin | T15: =VLOOKUP(A15,'[5]2019'!$A$2:$B$24,2,0) -> Penitenciária de Ribeirão das Neves I - José Maria Alkimin | U15: =VLOOKUP(A15,'[6]2019'!$A$1:$B$24,2,0) -> Penitenciária de Ribeirão das Neves I - José Maria Alkimin | V15: =VLOOKUP(A15,'[7]2019'!$A$2:$B$24,2,0) -> Penitenciária de Ribeirão das Neves I - José Maria Alkimin
A16: 0183EF31316292210 | B16: 0183 | C16: EF | D16: 31 | E16: Minas Gerais | F16: São Joaquim de Bicas | G16: 3162922 | H16: 1 | I16: 3613291 | J16: Penitenciária de São Joaquim de Bicas I - Professor Jason Soares de Albergaria | K16: 0183EF31316292210 | L16: 0 | M16: 74 | N16: 0 | O16: 0 | P16: =VLOOKUP(A16,'[1]2019'!$A$1:$C$22,3,0) -> Penitenciária de São Joaquim de Bicas I - Professor Jason Soares de Albergaria | Q16: =VLOOKUP(A16,'[2]2019'!$A$2:$B$24,2,0) -> Penitenciária de São Joaquim de Bicas I - Professor Jason Soares de Albergaria | R16: =VLOOKUP(A16,'[3]2019'!$A$2:$B$24,2,0) -> Penitenciária de São Joaquim de Bicas I - Professor Jason Soares de Albergaria | S16: =VLOOKUP(A16,'[4]2019'!$A$2:$B$24,2,0) -> Penitenciária de São Joaquim de Bicas I - Professor Jason Soares de Albergaria | T16: =VLOOKUP(A16,'[5]2019'!$A$2:$B$24,2,0) -> Penitenciária de São Joaquim de Bicas I - Professor Jason Soares de Albergaria | U16: =VLOOKUP(A16,'[6]2019'!$A$1:$B$24,2,0) -> Penitenciária de São Joaquim de Bicas I - Professor Jason Soares de Albergaria | V16: =VLOOKUP(A16,'[7]2019'!$A$2:$B$24,2,0) -> Penitenciária de São Joaquim de Bicas I - Professor Jason Soares de Albergaria
A17: 0184EF31312670310 | B17: 0184 | C17: EF | D17: 31 | E17: Minas Gerais | F17: Francisco Sá | G17: 3126703 | H17: 1 | I17: 3577988 | J17: Penitenciária de Segurança Máxima de Francisco Sá I | K17: 0184EF31312670310 | L17: 0 | M17: 74 | N17: 0 | O17: 0 | P17: =VLOOKUP(A17,'[1]2019'!$A$1:$C$22,3,0) -> Penitenciária de Segurança Máxima de Francisco Sá I | Q17: =VLOOKUP(A17,'[2]2019'!$A$2:$B$24,2,0) -> Penitenciária de Segurança Máxima de Francisco Sá I | R17: =VLOOKUP(A17,'[3]2019'!$A$2:$B$24,2,0) -> Penitenciária de Segurança Máxima de Francisco Sá I | S17: =VLOOKUP(A17,'[4]2019'!$A$2:$B$24,2,0) -> Penitenciária de Segurança Máxima de Francisco Sá I | T17: =VLOOKUP(A17,'[5]2019'!$A$2:$B$24,2,0) -> Penitenciária de Segurança Máxima de Francisco Sá I | U17: =VLOOKUP(A17,'[6]2019'!$A$1:$B$24,2,0) -> Penitenciária de Segurança Máxima de Francisco Sá I | V17: =VLOOKUP(A17,'[7]2019'!$A$2:$B$24,2,0) -> Penitenciária de Segurança Máxima de Francisco Sá I
A18: 0185EF31316860600 | B18: 0185 | C18: EF | D18: 31 | E18: Minas Gerais | F18: Teófilo Otoni | G18: 3168606 | H18: 0 | J18: Penitenciária de Teófilo Otoni I | K18: 0185EF31316860600 | L18: 0 | M18: 74 | N18: 0 | O18: 0 | P18: =VLOOKUP(A18,'[1]2019'!$A$1:$C$22,3,0) -> Penitenciária de Teófilo Otoni I | Q18: =VLOOKUP(A18,'[2]2019'!$A$2:$B$24,2,0) -> Penitenciária de Teófilo Otoni I | R18: =VLOOKUP(A18,'[3]2019'!$A$2:$B$24,2,0) -> Penitenciária de Teófilo Otoni I | S18: =VLOOKUP(A18,'[4]2019'!$A$2:$B$24,2,0) -> Penitenciária de Teófilo Otoni I | T18: =VLOOKUP(A18,'[5]2019'!$A$2:$B$24,2,0) -> Penitenciária de Teófilo Otoni I | U18: =VLOOKUP(A18,'[6]2019'!$A$1:$B$24,2,0) -> Penitenciária de Teófilo Otoni I | V18: =VLOOKUP(A18,'[7]2019'!$A$2:$B$24,2,0) -> Penitenciária de Teófilo Otoni I
A19: 0186EF31316930702 | B19: 0186 | C19: EF | D19: 31 | E19: Minas Gerais | F19: Três Corações | G19: 3169307 | H19: 0 | J19: Penitenciária de Três Corações I | K19: 0186EF31316930702 | L19: 2 | M19: 0 | N19: 0 | O19: 0 | P19: =VLOOKUP(A19,'[1]2019'!$A$1:$C$22,3,0) -> Penitenciária de Três Corações I | Q19: =VLOOKUP(A19,'[2]2019'!$A$2:$B$24,2,0) -> Penitenciária de Três Corações I | R19: =VLOOKUP(A19,'[3]2019'!$A$2:$B$24,2,0) -> Penitenciária de Três Corações I | S19: =VLOOKUP(A19,'[4]2019'!$A$2:$B$24,2,0) -> Penitenciária de Três Corações I | T19: =VLOOKUP(A19,'[5]2019'!$A$2:$B$24,2,0) -> Penitenciária de Três Corações I | U19: =VLOOKUP(A19,'[6]2019'!$A$1:$B$24,2,0) -> Penitenciária de Três Corações I | V19: =VLOOKUP(A19,'[7]2019'!$A$2:$B$24,2,0) -> Penitenciária de Três Corações I
A20: 0187EF31317010712 | B20: 0187 | C20: EF | D20: 31 | E20: Minas Gerais | F20: Uberaba | G20: 3170107 | H20: 1 | I20: 5984963 | J20: Penitenciária de Uberaba I | K20: 0187EF31317010712 | L20: 2 | M20: 74 | N20: 0 | O20: 0 | P20: =VLOOKUP(A20,'[1]2019'!$A$1:$C$22,3,0) -> Penitenciária de Uberaba I | Q20: =VLOOKUP(A20,'[2]2019'!$A$2:$B$24,2,0) -> Penitenciária de Uberaba I | R20: =VLOOKUP(A20,'[3]2019'!$A$2:$B$24,2,0) -> Penitenciária de Uberaba I | S20: =VLOOKUP(A20,'[4]2019'!$A$2:$B$24,2,0) -> Penitenciária de Uberaba I | T20: =VLOOKUP(A20,'[5]2019'!$A$2:$B$24,2,0) -> Penitenciária de Uberaba I | U20: =VLOOKUP(A20,'[6]2019'!$A$1:$B$24,2,0) -> Penitenciária de Uberaba I - PROFESSOR ALUIZIO IGNÁCIO DE OLIVEIRA | V20: =VLOOKUP(A20,'[7]2019'!$A$2:$B$24,2,0) -> Penitenciária de Uberaba I
A21: 0188EF31317020612 | B21: 0188 | C21: EF | D21: 31 | E21: Minas Gerais | F21: Uberlândia | G21: 3170206 | H21: 1 | I21: 3894304 | J21: Penitenciária de Uberlândia I - Professor João Pimenta Da Veiga | K21: 0188EF31317020612 | L21: 2 | M21: 0 | N21: 0 | O21: 0 | P21: =VLOOKUP(A21,'[1]2019'!$A$1:$C$22,3,0) -> Penitenciária de Uberlândia I - Professor João Pimenta Da Veiga | Q21: =VLOOKUP(A21,'[2]2019'!$A$2:$B$24,2,0) -> Penitenciária de Uberlândia I - Professor João Pimenta Da Veiga | R21: =VLOOKUP(A21,'[3]2019'!$A$2:$B$24,2,0) -> Penitenciária de Uberlândia I - Professor João Pimenta Da Veiga | S21: =VLOOKUP(A21,'[4]2019'!$A$2:$B$24,2,0) -> Penitenciária de Uberlândia I - Professor João Pimenta Da Veiga | T21: =VLOOKUP(A21,'[5]2019'!$A$2:$B$24,2,0) -> Penitenciária de Uberlândia I - Professor João Pimenta Da Veiga | U21: =VLOOKUP(A21,'[6]2019'!$A$1:$B$24,2,0) -> Penitenciária de Uberlândia I - Professor João Pimenta Da Veiga | V21: =VLOOKUP(A21,'[7]2019'!$A$2:$B$24,2,0) -> Penitenciária de Uberlândia I - Professor João Pimenta Da Veiga
A22: 0189EF31317040402 | B22: 0189 | C22: EF | D22: 31 | E22: Minas Gerais | F22: Unaí | G22: 3170404 | H22: 0 | J22: Penitenciária de Unaí I - Agostinho de Oliveira Júnior | K22: 0189EF31317040402 | L22: 2 | M22: 0 | N22: 0 | O22: 0 | P22: =VLOOKUP(A22,'[1]2019'!$A$1:$C$22,3,0) -> Penitenciária de Unaí I - Agostinho de Oliveira Júnior | Q22: =VLOOKUP(A22,'[2]2019'!$A$2:$B$24,2,0) -> Penitenciária de Unaí I - Agostinho de Oliveira Júnior | R22: =VLOOKUP(A22,'[3]2019'!$A$2:$B$24,2,0) -> Penitenciária de Unaí I - Agostinho de Oliveira Júnior | S22: =VLOOKUP(A22,'[4]2019'!$A$2:$B$24,2,0) -> Penitenciária de Unaí I - Agostinho de Oliveira Júnior | T22: =VLOOKUP(A22,'[5]2019'!$A$2:$B$24,2,0) -> Penitenciária de Unaí I - Agostinho de Oliveira Júnior | U22: =VLOOKUP(A22,'[6]2019'!$A$1:$B$24,2,0) -> Penitenciária de Unaí I - Agostinho de Oliveira Júnior | V22: =VLOOKUP(A22,'[7]2019'!$A$2:$B$24,2,0) -> Penitenciária de Unaí I - Agostinho de Oliveira Júnior
A23: 0227EF31315460610 | B23: 0227 | C23: EF | D23: 31 | E23: Minas Gerais | F23: Ribeirão das Neves | G23: 3154606 | H23: 1 | I23: 7403542 | J23: Complexo Público Privado de Ribeirão das Neves I | K23: 0227EF31315460610 | L23: 0 | M23: 74 | N23: 0 | O23: 2 | P23: =VLOOKUP(A23,'[1]2019'!$A$1:$C$22,3,0) -> #N/A | Q23: =VLOOKUP(A23,'[2]2019'!$A$2:$B$24,2,0) -> Complexo Público Privado de Ribeirão das Neves I | R23: =VLOOKUP(A23,'[3]2019'!$A$2:$B$24,2,0) -> Complexo Público Privado de Ribeirão das Neves I | S23: =VLOOKUP(A23,'[4]2019'!$A$2:$B$24,2,0) -> Complexo Público Privado de Ribeirão das Neves I | T23: =VLOOKUP(A23,'[5]2019'!$A$2:$B$24,2,0) -> Complexo Público Privado de Ribeirão das Neves I | U23: =VLOOKUP(A23,'[6]2019'!$A$1:$B$24,2,0) -> Complexo Público Privado de Ribeirão das Neves I | V23: =VLOOKUP(A23,'[7]2019'!$A$2:$B$24,2,0) -> Complexo Público Privado de Ribeirão das Neves I
A24: 0228EF31315460610 | B24: 0228 | C24: EF | D24: 31 | E24: Minas Gerais | F24: Ribeirão das Neves | G24: 3154606 | H24: 1 | I24: 7403542 | J24: Complexo Público Privado de Ribeirão das Neves II | K24: 0228EF31315460610 | L24: 0 | M24: 74 | N24: 0 | O24: 2 | P24: =VLOOKUP(A24,'[1]2019'!$A$1:$C$22,3,0) -> #N/A | Q24: =VLOOKUP(A24,'[2]2019'!$A$2:$B$24,2,0) -> Complexo Público Privado de Ribeirão das Neves II | R24: =VLOOKUP(A24,'[3]2019'!$A$2:$B$24,2,0) -> Complexo Público Privado de Ribeirão das Neves II | S24: =VLOOKUP(A24,'[4]2019'!$A$2:$B$24,2,0) -> Complexo Público Privado de Ribeirão das Neves II | T24: =VLOOKUP(A24,'[5]2019'!$A$2:$B$24,2,0) -> Complexo Público Privado de Ribeirão das Neves II | U24: =VLOOKUP(A24,'[6]2019'!$A$1:$B$24,2,0) -> Complexo Público Privado de Ribeirão das Neves II | V24: =VLOOKUP(A24,'[7]2019'!$A$2:$B$24,2,0) -> Complexo Público Privado de Ribeirão das Neves II

Sheet 2019
A1: CHAVE | B1: Ocupação | C1: 1- Salários com a administração penitenciária | D1: 2 - Salários com outras administrações | E1: 3 - Pagamento a prestadores de serviço | F1: 4 - Aluguéis de bens imóveis, móveis, veículos e equipamentos de informática | G1: 5 - Água, luz, internet, telefone, lixo e esgoto | H1: 6 - Transportes e combustíveis | I1: 7 - Material de limpeza | J1: 8 - Material de escritório | K1: 9 - Manutenção predial | L1: 10 - Manutenção de equipamentos de segurança | M1: 11 - Manutenção de equipamentos de informática | N1: 12 - Aquisição de equipamentos de segurança, de informática, veículos, móveis e imóveis | O1: 13 - Atividades laborais e educacionais | P1: 14 - Alimentação | Q1: 15 - Material de higiene pessoal | R1: 16 - Colchões, uniformes, roupas de cama e banho | S1: 17- Recursos para assistência à saúde do preso (médica, odontológica, psicológica, terapia ocupacional, etc.) | T1: Total | U1: Total/ocup | V1: diaria
A2: 0169MO31310620002 | B2: 1178.5 | C2: =VLOOKUP(A2,'[1]2019'!$A$2:$D$22,4,0) -> 7301291.2 | F2: =VLOOKUP(A2,'[3]2019'!$A$2:$H$24,8,0) -> 16268.52 | G2: =VLOOKUP(A2,'[3]2019'!$A$2:$I$24,9,0) -> 16323.08 | H2: =VLOOKUP(A2,'[6]2019'!$A$2:$E$24,5,0) -> 2731.34 | I2: =VLOOKUP(A2,'[2]2019'!$A$2:$C$24,3,0) -> 3366.95 | J2: =VLOOKUP(A2,'[2]2019'!$A$2:$I$24,4,0) -> 19487.18 | K2: =VLOOKUP(A2,'[5]2019'!$A$2:$M$24,13,0) -> 0 | L2: =VLOOKUP(A2,'[2]2019'!$A$2:$E$24,5,0) -> 0 | M2: =VLOOKUP(A2,'[3]2019'!$A$2:$O$24,15,0) -> 13440 | N2: =VLOOKUP(A2,'[2]2019'!$A$2:$F$24,6,0) -> 0 | O2: =VLOOKUP(A2,'[7]2019'!$A$2:$C$24,3,0) -> R$ - | P2: =VLOOKUP(A2,'[4]2019'!$A$2:$R$24,18,0) -> 0 | Q2: =VLOOKUP(A2,'[2]2019'!$A$2:$G$2,7,0) -> 1771.39 | R2: =VLOOKUP(A2,'[2]2019'!$A$2:$H$24,8,0) -> 0 | S2: =VLOOKUP(A2,'[2]2019'!$A$2:$I$24,9,0) -> 0 | T2: =SUM(C2:S2) -> 7374679.7 | U2: =T2/B2 -> 6257.6832 | V2: =U2/365 -> 17.144338
A3: 0170EF31310620011 | B3: =VLOOKUP(A3,[8]Ocupação!$E$4:$F$25,2,0) -> 433.08333 | C3: =VLOOKUP(A3,'[1]2019'!$A$2:$D$22,4,0) -> 15251488 | F3: =VLOOKUP(A3,'[3]2019'!$A$2:$H$24,8,0) -> 204786.39 | G3: =VLOOKUP(A3,'[3]2019'!$A$2:$I$24,9,0) -> 26095.83 | H3: =VLOOKUP(A3,'[6]2019'!$A$2:$E$24,5,0) -> 11100.69 | I3: =VLOOKUP(A3,'[2]2019'!$A$2:$C$24,3,0) -> 26063.44 | J3: =VLOOKUP(A3,'[2]2019'!$A$2:$I$24,4,0) -> 10272.81 | K3: =VLOOKUP(A3,'[5]2019'!$A$2:$M$24,13,0) -> 399202.72 | L3: =VLOOKUP(A3,'[2]2019'!$A$2:$E$24,5,0) -> 0 | M3: =VLOOKUP(A3,'[3]2019'!$A$2:$O$24,15,0) -> 0 | N3: =VLOOKUP(A3,'[2]2019'!$A$2:$F$24,6,0) -> 219481.72 | O3: =VLOOKUP(A3,'[7]2019'!$A$2:$C$24,3,0) -> 2000 | P3: =VLOOKUP(A3,'[4]2019'!$A$2:$R$24,18,0) -> 1940520.7 | Q3: =VLOOKUP(A3,'[2]2019'!$A$2:$G$24,7,0) -> 62096.02 | R3: =VLOOKUP(A3,'[2]2019'!$A$2:$H$24,8,0) -> 54211.03 | S3: =VLOOKUP(A3,'[2]2019'!$A$2:$I$24,9,0) -> 88686.64 | T3: =SUM(C3:S3) -> 18296006 | U3: =T3/B3 -> 42245.925 | V3: =U3/365 -> 115.74226
A4: 0171EF31311430300 | B4: =VLOOKUP(A4,[8]Ocupação!$E$4:$F$25,2,0) -> 636.5 | C4: =VLOOKUP(A4,'[1]2019'!$A$2:$D$22,4,0) -> 12500357 | F4: =VLOOKUP(A4,'[3]2019'!$A$2:$H$24,8,0) -> 5705.48 | G4: =VLOOKUP(A4,'[3]2019'!$A$2:$I$24,9,0) -> 18866.76 | H4: =VLOOKUP(A4,'[6]2019'!$A$2:$E$24,5,0) -> 2362.98 | I4: =VLOOKUP(A4,'[2]2019'!$A$2:$C$24,3,0) -> 28565.1 | J4: =VLOOKUP(A4,'[2]2019'!$A$2:$I$24,4,0) -> 7807.23 | K4: =VLOOKUP(A4,'[5]2019'!$A$2:$M$24,13,0) -> 0 | L4: =VLOOKUP(A4,'[2]2019'!$A$2:$E$24,5,0) -> 0 | M4: =VLOOKUP(A4,'[3]2019'!$A$2:$O$24,15,0) -> 6720 | N4: =VLOOKUP(A4,'[2]2019'!$A$2:$F$24,6,0) -> 87119.23 | O4: =VLOOKUP(A4,'[7]2019'!$A$2:$C$24,3,0) -> 2000 | P4: =VLOOKUP(A4,'[4]2019'!$A$2:$R$24,18,0) -> 2557208.8 | Q4: =VLOOKUP(A4,'[2]2019'!$A$2:$G$24,7,0) -> 27204.25 | R4: =VLOOKUP(A4,'[2]2019'!$A$2:$H$24,8,0) -> 100179.15 | S4: =VLOOKUP(A4,'[2]2019'!$A$2:$I$24,9,0) -> 38450.64 | T4: =SUM(C4:S4) -> 15382547 | U4: =T4/B4 -> 24167.395 | V4: =U4/365 -> 66.212042
A5: 0172EF31311860112 | B5: =VLOOKUP(A5,[8]Ocupação!$E$4:$F$25,2,0) -> 2042.25 | C5: =VLOOKUP(A5,'[1]2019'!$A$2:$D$22,4,0) -> 46906686 | F5: =VLOOKUP(A5,'[3]2019'!$A$2:$H$24,8,0) -> 195039.15 | G5: =VLOOKUP(A5,'[3]2019'!$A$2:$I$24,9,0) -> 24452.34 | H5: =VLOOKUP(A5,'[6]2019'!$A$2:$E$24,5,0) -> 279735.06 | I5: =VLOOKUP(A5,'[2]2019'!$A$2:$C$24,3,0) -> 63405.9 | J5: =VLOOKUP(A5,'[2]2019'!$A$2:$I$24,4,0) -> 20766.85 | K5: =VLOOKUP(A5,'[5]2019'!$A$2:$M$24,13,0) -> 170457.99 | L5: =VLOOKUP(A5,'[2]2019'!$A$2:$E$24,5,0) -> 0 | M5: =VLOOKUP(A5,'[3]2019'!$A$2:$O$24,15,0) -> 13320 | N5: =VLOOKUP(A5,'[2]2019'!$A$2:$F$24,6,0) -> 678155.77 | O5: =VLOOKUP(A5,'[7]2019'!$A$2:$C$24,3,0) -> 15000 | P5: =VLOOKUP(A5,'[4]2019'!$A$2:$R$24,18,0) -> 8333730.1 | Q5: =VLOOKUP(A5,'[2]2019'!$A$2:$G$24,7,0) -> 119650.77 | R5: =VLOOKUP(A5,'[2]2019'!$A$2:$H$24,8,0) -> 339662.92 | S5: =VLOOKUP(A5,'[2]2019'!$A$2:$I$24,9,0) -> 92406.01 | T5: =SUM(C5:S5) -> 57252469 | U5: =T5/B5 -> 28034.016 | V5: =U5/365 -> 76.805523
A6: 0173EF31312610910 | B6: =VLOOKUP(A6,[8]Ocupação!$E$4:$F$25,2,0) -> 835 | C6: =VLOOKUP(A6,'[1]2019'!$A$2:$D$22,4,0) -> 14076043 | F6: =VLOOKUP(A6,'[3]2019'!$A$2:$H$24,8,0) -> 5504.04 | G6: =VLOOKUP(A6,'[3]2019'!$A$2:$I$24,9,0) -> 14456.44 | H6: =VLOOKUP(A6,'[6]2019'!$A$2:$E$24,5,0) -> 8535.75 | I6: =VLOOKUP(A6,'[2]2019'!$A$2:$C$24,3,0) -> 29975.48 | J6: =VLOOKUP(A6,'[2]2019'!$A$2:$I$24,4,0) -> 9624.13 | K6: =VLOOKUP(A6,'[5]2019'!$A$2:$M$24,13,0) -> 0 | L6: =VLOOKUP(A6,'[2]2019'!$A$2:$E$24,5,0) -> 0 | M6: =VLOOKUP(A6,'[3]2019'!$A$2:$O$24,15,0) -> 6720 | N6: =VLOOKUP(A6,'[2]2019'!$A$2:$F$24,6,0) -> 174957.2 | O6: =VLOOKUP(A6,'[7]2019'!$A$2:$C$24,3,0) -> 2000 | P6: =VLOOKUP(A6,'[4]2019'!$A$2:$R$24,18,0) -> 3959235.5 | Q6: =VLOOKUP(A6,'[2]2019'!$A$2:$G$24,7,0) -> 31072.78 | R6: =VLOOKUP(A6,'[2]2019'!$A$2:$H$24,8,0) -> 233983.66 | S6: =VLOOKUP(A6,'[2]2019'!$A$2:$I$24,9,0) -> 53964.82 | T6: =SUM(C6:S6) -> 18606073 | U6: =T6/B6 -> 22282.722 | V6: =U6/365 -> 61.048552
A7: 0174EF31312770100 | B7: =VLOOKUP(A7,[8]Ocupação!$E$4:$F$25,2,0) -> 1284 | C7: =VLOOKUP(A7,'[1]2019'!$A$2:$D$22,4,0) -> 22983019 | F7: =VLOOKUP(A7,'[3]2019'!$A$2:$H$24,8,0) -> 208799.88 | G7: =VLOOKUP(A7,'[3]2019'!$A$2:$I$24,9,0) -> 25177.85 | H7: =VLOOKUP(A7,'[6]2019'!$A$2:$E$24,5,0) -> 26442.4 | I7: =VLOOKUP(A7,'[2]2019'!$A$2:$C$24,3,0) -> 39224.32 | J7: =VLOOKUP(A7,'[2]2019'!$A$2:$I$24,4,0) -> 10468.27 | K7: =VLOOKUP(A7,'[5]2019'!$A$2:$M$24,13,0) -> 7060.2 | L7: =VLOOKUP(A7,'[2]2019'!$A$2:$E$24,5,0) -> 0 | M7: =VLOOKUP(A7,'[3]2019'!$A$2:$O$24,15,0) -> 0 | N7: =VLOOKUP(A7,'[2]2019'!$A$2:$F$24,6,0) -> 221778.83 | O7: =VLOOKUP(A7,'[7]2019'!$A$2:$C$24,3,0) -> 3000 | P7: =VLOOKUP(A7,'[4]2019'!$A$2:$R$24,18,0) -> 5215089.8 | Q7: =VLOOKUP(A7,'[2]2019'!$A$2:$G$24,7,0) -> 33252.75 | R7: =VLOOKUP(A7,'[2]2019'!$A$2:$H$24,8,0) -> 285142.1 | S7: =VLOOKUP(A7,'[2]2019'!$A$2:$I$24,9,0) -> 62290.77 | T7: =SUM(C7:S7) -> 29120746 | U7: =T7/B7 -> 22679.709 | V7: =U7/365 -> 62.136188
A8: 0175EF31313115800 | B8: =VLOOKUP(A8,[8]Ocupação!$E$4:$F$25,2,0) -> 1365.8333 | C8: =VLOOKUP(A8,'[1]2019'!$A$2:$D$22,4,0) -> 18396286 | F8: =VLOOKUP(A8,'[3]2019'!$A$2:$H$24,8,0) -> 203227.78 | G8: =VLOOKUP(A8,'[3]2019'!$A$2:$I$24,9,0) -> 17957.04 | H8: =VLOOKUP(A8,'[6]2019'!$A$2:$E$24,5,0) -> 285600 | I8: =VLOOKUP(A8,'[2]2019'!$A$2:$C$24,3,0) -> 37473.9 | J8: =VLOOKUP(A8,'[2]2019'!$A$2:$I$24,4,0) -> 6235.3 | K8: =VLOOKUP(A8,'[5]2019'!$A$2:$M$24,13,0) -> 44708.11 | L8: =VLOOKUP(A8,'[2]2019'!$A$2:$E$24,5,0) -> 0 | M8: =VLOOKUP(A8,'[3]2019'!$A$2:$O$24,15,0) -> 6720 | N8: =VLOOKUP(A8,'[2]2019'!$A$2:$F$24,6,0) -> 129435.46 | O8: =VLOOKUP(A8,'[7]2019'!$A$2:$C$24,3,0) -> 12000 | P8: =VLOOKUP(A8,'[4]2019'!$A$2:$R$24,18,0) -> 5529200 | Q8: =VLOOKUP(A8,'[2]2019'!$A$2:$G$24,7,0) -> 48383.88 | R8: =VLOOKUP(A8,'[2]2019'!$A$2:$H$24,8,0) -> 218481.47 | S8: =VLOOKUP(A8,'[2]2019'!$A$2:$I$24,9,0) -> 58375.56 | T8: =SUM(C8:S8) -> 24994085 | U8: =T8/B8 -> 18299.513 | V8: =U8/365 -> 50.135652
A9: 0176EF31313670212 | B9: =VLOOKUP(A9,[8]Ocupação!$E$4:$F$25,2,0) -> 455.75 | C9: =VLOOKUP(A9,'[1]2019'!$A$2:$D$22,4,0) -> 20529485 | F9: =VLOOKUP(A9,'[3]2019'!$A$2:$H$24,8,0) -> 9371.95 | G9: =VLOOKUP(A9,'[3]2019'!$A$2:$I$24,9,0) -> 15545.56 | H9: =VLOOKUP(A9,'[6]2019'!$A$2:$E$24,5,0) -> 4194.88 | I9: =VLOOKUP(A9,'[2]2019'!$A$2:$C$24,3,0) -> 23537.53 | J9: =VLOOKUP(A9,'[2]2019'!$A$2:$I$24,4,0) -> 5555.92 | K9: =VLOOKUP(A9,'[5]2019'!$A$2:$M$24,13,0) -> 11373758 | L9: =VLOOKUP(A9,'[2]2019'!$A$2:$E$24,5,0) -> 0 | M9: =VLOOKUP(A9,'[3]2019'!$A$2:$O$24,15,0) -> 0 | N9: =VLOOKUP(A9,'[2]2019'!$A$2:$F$24,6,0) -> 112520.03 | O9: =VLOOKUP(A9,'[7]2019'!$A$2:$C$24,3,0) -> 3000 | P9: =VLOOKUP(A9,'[4]2019'!$A$2:$R$24,18,0) -> 2393240.7 | Q9: =VLOOKUP(A9,'[2]2019'!$A$2:$G$24,7,0) -> 21063.8 | R9: =VLOOKUP(A9,'[2]2019'!$A$2:$H$24,8,0) -> 100479.86 | S9: =VLOOKUP(A9,'[2]2019'!$A$2:$I$24,9,0) -> 37943.68 | T9: =SUM(C9:S9) -> 34629697 | U9: =T9/B9 -> 75983.976 | V9: =U9/365 -> 208.17528
A10: 0177EF31313670202 | B10: =VLOOKUP(A10,[8]Ocupação!$E$4:$F$25,2,0) -> 941.66667 | C10: =VLOOKUP(A10,'[1]2019'!$A$2:$D$22,4,0) -> 21645456 | F10: =VLOOKUP(A10,'[3]2019'!$A$2:$H$24,8,0) -> 5989.03 | G10: =VLOOKUP(A10,'[3]2019'!$A$2:$I$24,9,0) -> 9855.36 | H10: =VLOOKUP(A10,'[6]2019'!$A$2:$E$24,5,0) -> 2463.89 | I10: =VLOOKUP(A10,'[2]2019'!$A$2:$C$24,3,0) -> 23784.28 | J10: =VLOOKUP(A10,'[2]2019'!$A$2:$I$24,4,0) -> 7443.64 | K10: =VLOOKUP(A10,'[5]2019'!$A$2:$M$24,13,0) -> 0 | L10: =VLOOKUP(A10,'[2]2019'!$A$2:$E$24,5,0) -> 0 | M10: =VLOOKUP(A10,'[3]2019'!$A$2:$O$24,15,0) -> 0 | N10: =VLOOKUP(A10,'[2]2019'!$A$2:$F$24,6,0) -> 79410.01 | O10: =VLOOKUP(A10,'[7]2019'!$A$2:$C$24,3,0) -> 6000 | P10: =VLOOKUP(A10,'[4]2019'!$A$2:$R$24,18,0) -> 4342507.5 | Q10: =VLOOKUP(A10,'[2]2019'!$A$2:$G$24,7,0) -> 25419.72 | R10: =VLOOKUP(A10,'[2]2019'!$A$2:$H$24,8,0) -> 129501.87 | S10: =VLOOKUP(A10,'[2]2019'!$A$2:$I$24,9,0) -> 72933.62 | T10: =SUM(C10:S10) -> 26350765 | U10: =T10/B10 -> 27983.113 | V10: =U10/365 -> 76.666063
A11: 0178EF31314390610 | B11: =VLOOKUP(A11,[8]Ocupação!$E$4:$F$25,2,0) -> 834 | C11: =VLOOKUP(A11,'[1]2019'!$A$2:$D$22,4,0) -> 15154379 | F11: =VLOOKUP(A11,'[3]2019'!$A$2:$H$24,8,0) -> 2328.55 | G11: =VLOOKUP(A11,'[3]2019'!$A$2:$I$24,9,0) -> 17118.75 | H11: =VLOOKUP(A11,'[6]2019'!$A$2:$E$24,5,0) -> 10447.13 | I11: =VLOOKUP(A11,'[2]2019'!$A$2:$C$24,3,0) -> 25960.21 | J11: =VLOOKUP(A11,'[2]2019'!$A$2:$I$24,4,0) -> 4312.48 | K11: =VLOOKUP(A11,'[5]2019'!$A$2:$M$24,13,0) -> 0 | L11: =VLOOKUP(A11,'[2]2019'!$A$2:$E$24,5,0) -> 0 | M11: =VLOOKUP(A11,'[3]2019'!$A$2:$O$24,15,0) -> 6720 | N11: =VLOOKUP(A11,'[2]2019'!$A$2:$F$24,6,0) -> 101670.9 | O11: =VLOOKUP(A11,'[7]2019'!$A$2:$C$24,3,0) -> 15000 | P11: =VLOOKUP(A11,'[4]2019'!$A$2:$R$24,18,0) -> 3575982.2 | Q11: =VLOOKUP(A11,'[2]2019'!$A$2:$G$24,7,0) -> 41320.03 | R11: =VLOOKUP(A11,'[2]2019'!$A$2:$H$24,8,0) -> 112126.07 | S11: =VLOOKUP(A11,'[2]2019'!$A$2:$I$24,9,0) -> 57193.62 | T11: =SUM(C11:S11) -> 19124559 | U11: =T11/B11 -> 22931.126 | V11: =U11/365 -> 62.825004
A12: 0179EF31314710512 | B12: =VLOOKUP(A12,[8]Ocupação!$E$4:$F$25,2,0) -> 874.83333 | C12: =VLOOKUP(A12,'[1]2019'!$A$2:$D$22,4,0) -> 13137816 | F12: =VLOOKUP(A12,'[3]2019'!$A$2:$H$24,8,0) -> 7940.29 | G12: =VLOOKUP(A12,'[3]2019'!$A$2:$I$24,9,0) -> 52912.65 | H12: =VLOOKUP(A12,'[6]2019'!$A$2:$E$24,5,0) -> 97544.43 | I12: =VLOOKUP(A12,'[2]2019'!$A$2:$C$24,3,0) -> 41244.53 | J12: =VLOOKUP(A12,'[2]2019'!$A$2:$I$24,4,0) -> 12990.69 | K12: =VLOOKUP(A12,'[5]2019'!$A$2:$M$24,13,0) -> 0 | L12: =VLOOKUP(A12,'[2]2019'!$A$2:$E$24,5,0) -> 0 | M12: =VLOOKUP(A12,'[3]2019'!$A$2:$O$24,15,0) -> 6720 | N12: =VLOOKUP(A12,'[2]2019'!$A$2:$F$24,6,0) -> 160889.31 | O12: =VLOOKUP(A12,'[7]2019'!$A$2:$C$24,3,0) -> R$ - | P12: =VLOOKUP(A12,'[4]2019'!$A$2:$R$24,18,0) -> 3991358.9 | Q12: =VLOOKUP(A12,'[2]2019'!$A$2:$G$24,7,0) -> 59939.3 | R12: =VLOOKUP(A12,'[2]2019'!$A$2:$H$24,8,0) -> 179693.42 | S12: =VLOOKUP(A12,'[2]2019'!$A$2:$I$24,9,0) -> 45361.83 | T12: =SUM(C12:S12) -> 17794411 | U12: =T12/B12 -> 20340.345 | V12: =U12/365 -> 55.726971
A13: 0180EF31314810310 | B13: =VLOOKUP(A13,[8]Ocupação!$E$4:$F$25,2,0) -> 1331.9167 | C13: =VLOOKUP(A13,'[1]2019'!$A$2:$D$22,4,0) -> 21071368 | F13: =VLOOKUP(A13,'[3]2019'!$A$2:$H$24,8,0) -> 204060.85 | G13: =VLOOKUP(A13,'[3]2019'!$A$2:$I$24,9,0) -> 18036.85 | H13: =VLOOKUP(A13,'[6]2019'!$A$2:$E$24,5,0) -> 76671.2 | I13: =VLOOKUP(A13,'[2]2019'!$A$2:$C$24,3,0) -> 41989.22 | J13: =VLOOKUP(A13,'[2]2019'!$A$2:$I$24,4,0) -> 17683.43 | K13: =VLOOKUP(A13,'[5]2019'!$A$2:$M$24,13,0) -> 0 | L13: =VLOOKUP(A13,'[2]2019'!$A$2:$E$24,5,0) -> 0 | M13: =VLOOKUP(A13,'[3]2019'!$A$2:$O$24,15,0) -> 12720 | N13: =VLOOKUP(A13,'[2]2019'!$A$2:$F$24,6,0) -> 187658.57 | O13: =VLOOKUP(A13,'[7]2019'!$A$2:$C$24,3,0) -> 1000 | P13: =VLOOKUP(A13,'[4]2019'!$A$2:$R$24,18,0) -> 4894364.9 | Q13: =VLOOKUP(A13,'[2]2019'!$A$2:$G$24,7,0) -> 71062.26 | R13: =VLOOKUP(A13,'[2]2019'!$A$2:$H$24,8,0) -> 343584.89 | S13: =VLOOKUP(A13,'[2]2019'!$A$2:$I$24,9,0) -> 50349.22 | T13: =SUM(C13:S13) -> 26990549 | U13: =T13/B13 -> 20264.443 | V13: =U13/365 -> 55.519022
A14: 0181EF31315210510 | B14: =VLOOKUP(A14,[8]Ocupação!$E$4:$F$25,2,0) -> 1113.0833 | C14: =VLOOKUP(A14,'[1]2019'!$A$2:$D$22,4,0) -> 15452574 | F14: =VLOOKUP(A14,'[3]2019'!$A$2:$H$24,8,0) -> 209344.01 | G14: =VLOOKUP(A14,'[3]2019'!$A$2:$I$24,9,0) -> 17301.25 | H14: =VLOOKUP(A14,'[6]2019'!$A$2:$E$24,5,0) -> 316241.2 | I14: =VLOOKUP(A14,'[2]2019'!$A$2:$C$24,3,0) -> 35315.18 | J14: =VLOOKUP(A14,'[2]2019'!$A$2:$I$24,4,0) -> 9982.53 | K14: =VLOOKUP(A14,'[5]2019'!$A$2:$M$24,13,0) -> 0 | L14: =VLOOKUP(A14,'[2]2019'!$A$2:$E$24,5,0) -> 0 | M14: =VLOOKUP(A14,'[3]2019'!$A$2:$O$24,15,0) -> 6720 | N14: =VLOOKUP(A14,'[2]2019'!$A$2:$F$24,6,0) -> 231555.64 | O14: =VLOOKUP(A14,'[7]2019'!$A$2:$C$24,3,0) -> 9000 | P14: =VLOOKUP(A14,'[4]2019'!$A$2:$R$24,18,0) -> 4713862 | Q14: =VLOOKUP(A14,'[2]2019'!$A$2:$G$24,7,0) -> 45431.42 | R14: =VLOOKUP(A14,'[2]2019'!$A$2:$H$24,8,0) -> 83228.76 | S14: =VLOOKUP(A14,'[2]2019'!$A$2:$I$24,9,0) -> 43191.34 | T14: =SUM(C14:S14) -> 21173747 | U14: =T14/B14 -> 19022.607 | V14: =U14/365 -> 52.116733
... A24: 0228EF31315460610 | B24: =VLOOKUP(A24,[8]Ocupação!$E$4:$F$25,2,0) -> 664.66667 | C24: =VLOOKUP(A24,'[1]2019'!$A$2:$D$22,4,0) -> #N/A | F24: =VLOOKUP(A24,'[3]2019'!$A$2:$H$24,8,0) -> NA | G24: =VLOOKUP(A24,'[3]2019'!$A$2:$I$24,9,0) -> NA | H24: =VLOOKUP(A24,'[6]2019'!$A$2:$E$24,5,0) -> 0 | I24: =VLOOKUP(A24,'[2]2019'!$A$2:$C$24,3,0) -> N/A | J24: =VLOOKUP(A24,'[2]2019'!$A$2:$I$24,4,0) -> N/A | K24: =VLOOKUP(A24,'[5]2019'!$A$2:$M$24,13,0) -> 0 | L24: =VLOOKUP(A24,'[2]2019'!$A$2:$E$24,5,0) -> N/A | M24: =VLOOKUP(A24,'[3]2019'!$A$2:$O$24,15,0) -> NA | N24: =VLOOKUP(A24,'[2]2019'!$A$2:$F$24,6,0) -> N/A | O24: =VLOOKUP(A24,'[7]2019'!$A$2:$C$24,3,0) -> R$ - | P24: =VLOOKUP(A24,'[4]2019'!$A$2:$R$24,18,0) -> 0 | Q24: =VLOOKUP(A24,'[2]2019'!$A$2:$G$24,7,0) -> N/A | R24: =VLOOKUP(A24,'[2]2019'!$A$2:$H$24,8,0) -> N/A | S24: =VLOOKUP(A24,'[2]2019'!$A$2:$I$24,9,0) -> N/A | T24: =SUM(C24:S24) -> #N/A | U24: =T24/B24 -> #N/A | V24: =U24/365 -> #N/A

Sheet 2020
A1: CHAVE | C1: 1- Salários com a administração penitenciária | D1: 2 - Salários com outras administrações | E1: 3 - Pagamento a prestadores de serviço | F1: 4 - Aluguéis de bens imóveis, móveis, veículos e equipamentos de informática | G1: 5 - Água, luz, internet, telefone, lixo e esgoto | H1: 6 - Transportes e combustíveis | I1: 7 - Material de limpeza | J1: 8 - Material de escritório | K1: 9 - Manutenção predial | L1: 10 - Manutenção de equipamentos de segurança | M1: 11 - Manutenção de equipamentos de informática | N1: 12 - Aquisição de equipamentos de segurança, de informática, veículos, móveis e imóveis | O1: 13 - Atividades laborais e educacionais | P1: 14 - Alimentação | Q1: 15 - Material de higiene pessoal | R1: 16 - Colchões, uniformes, roupas de cama e banho | S1: 17- Recursos para assistência à saúde do preso (médica, odontológica, psicológica, terapia ocupacional, etc.) | T1: Total | U1: Total/ocup | V1: diaria
A2: 0169MO31310620002 | B2: 2456.8333 | C2: =VLOOKUP(A2,'[1]2020'!$A$1:$D$22,4,0) -> 7655672.4 | F2: =VLOOKUP(A2,'[3]2020'!$A$2:$H$24,8,0) -> 10690.05 | G2: =VLOOKUP(A2,'[3]2020'!$A$2:$I$24,9,0) -> 13988.05 | H2: =VLOOKUP(A2,'[6]2020'!$A$2:$F$24,6,0) -> 2227.82 | I2: =VLOOKUP(A2,'[2]2020'!$A$2:$C$24,3,0) -> 3298.11 | J2: =VLOOKUP(A2,'[2]2020'!$A$2:$E$24,4,0) -> 12400.53 | K2: =VLOOKUP(A2,'[5]2020'!$A$2:$M$24,13,0) -> 17401.55 | L2: =VLOOKUP(A2,'[2]2020'!$A$2:$E$24,5,0) -> 0 | M2: =VLOOKUP(A2,'[3]2020'!$A$2:$O$24,15,0) -> 13565.44 | N2: =VLOOKUP(A2,'[2]2020'!$A$2:$F$24,6,0) -> 12582.82 | O2: =VLOOKUP(A2,'[7]2020'!$A$2:$C$24,3,0) -> 0 | P2: =VLOOKUP(A2,'[4]2020'!$A$2:$R$24,18,0) -> 0 | Q2: =VLOOKUP(A2,'[2]2020'!$A$2:$G$24,7,0) -> 2176.45 | R2: =VLOOKUP(A2,'[2]2020'!$A$2:$I$24,8,0) -> 0 | S2: =VLOOKUP(A2,'[2]2020'!$A$2:$I$24,9,0) -> 0 | T2: =SUM(C2:S2) -> 7744003.2 | U2: =T2/B2 -> 3152.0263 | V2: =U2/365 -> 8.6356884
A3: 0170EF31310620011 | B3: =VLOOKUP(A3,[8]Ocupação!$E$27:$F$48,2,0) -> 320.83333 | C3: =VLOOKUP(A3,'[1]2020'!$A$1:$D$22,4,0) -> 15326602 | F3: =VLOOKUP(A3,'[3]2020'!$A$2:$H$24,8,0) -> 204274.05 | G3: =VLOOKUP(A3,'[3]2020'!$A$2:$I$24,9,0) -> 16863.16 | H3: =VLOOKUP(A3,'[6]2020'!$A$2:$F$24,6,0) -> 19598.88 | I3: =VLOOKUP(A3,'[2]2020'!$A$2:$C$24,3,0) -> 15096.28 | J3: =VLOOKUP(A3,'[2]2020'!$A$2:$E$24,4,0) -> 8838.32 | K3: =VLOOKUP(A3,'[5]2020'!$A$2:$M$24,13,0) -> 0 | L3: =VLOOKUP(A3,'[2]2020'!$A$2:$E$24,5,0) -> 0 | M3: =VLOOKUP(A3,'[3]2020'!$A$2:$O$24,15,0) -> 0 | N3: =VLOOKUP(A3,'[2]2020'!$A$2:$F$24,6,0) -> 30974.27 | O3: =VLOOKUP(A3,'[7]2020'!$A$2:$C$24,3,0) -> 8000 | P3: =VLOOKUP(A3,'[4]2020'!$A$2:$R$24,18,0) -> 1360365.8 | Q3: =VLOOKUP(A3,'[2]2020'!$A$2:$G$24,7,0) -> 54264.63 | R3: =VLOOKUP(A3,'[2]2020'!$A$2:$I$24,8,0) -> 58138.89 | S3: =VLOOKUP(A3,'[2]2020'!$A$2:$I$24,9,0) -> 70572.9 | T3: =SUM(C3:S3) -> 17173589 | U3: =T3/B3 -> 53528.07 | V3: =U3/365 -> 146.65225
A4: 0171EF31311430300 | B4: =VLOOKUP(A4,[8]Ocupação!$E$27:$F$48,2,0) -> 543.66667 | C4: =VLOOKUP(A4,'[1]2020'!$A$1:$D$22,4,0) -> 13885614 | F4: =VLOOKUP(A4,'[3]2020'!$A$2:$H$24,8,0) -> 137646.52 | G4: =VLOOKUP(A4,'[3]2020'!$A$2:$I$24,9,0) -> 13837.04 | H4: =VLOOKUP(A4,'[6]2020'!$A$2:$F$24,6,0) -> 54362.96 | I4: =VLOOKUP(A4,'[2]2020'!$A$2:$C$24,3,0) -> 18645.01 | J4: =VLOOKUP(A4,'[2]2020'!$A$2:$E$24,4,0) -> 15243.87 | K4: =VLOOKUP(A4,'[5]2020'!$A$2:$M$24,13,0) -> 0 | L4: =VLOOKUP(A4,'[2]2020'!$A$2:$E$24,5,0) -> 0 | M4: =VLOOKUP(A4,'[3]2020'!$A$2:$O$24,15,0) -> 6782.72 | N4: =VLOOKUP(A4,'[2]2020'!$A$2:$F$24,6,0) -> 51419.54 | O4: =VLOOKUP(A4,'[7]2020'!$A$2:$C$24,3,0) -> 8000 | P4: =VLOOKUP(A4,'[4]2020'!$A$2:$R$24,18,0) -> 2415263.9 | Q4: =VLOOKUP(A4,'[2]2020'!$A$2:$G$24,7,0) -> 34206.48 | R4: =VLOOKUP(A4,'[2]2020'!$A$2:$I$24,8,0) -> 60109.08 | S4: =VLOOKUP(A4,'[2]2020'!$A$2:$I$24,9,0) -> 30965.55 | T4: =SUM(C4:S4) -> 16732097 | U4: =T4/B4 -> 30776.389 | V4: =U4/365 -> 84.318873
A5: 0172EF31311860112 | B5: =VLOOKUP(A5,[8]Ocupação!$E$27:$F$48,2,0) -> 1939.25 | C5: =VLOOKUP(A5,'[1]2020'!$A$1:$D$22,4,0) -> 51521504 | F5: =VLOOKUP(A5,'[3]2020'!$A$2:$H$24,8,0) -> 253914.83 | G5: =VLOOKUP(A5,'[3]2020'!$A$2:$I$24,9,0) -> 26512.55 | H5: =VLOOKUP(A5,'[6]2020'!$A$2:$F$24,6,0) -> 503970.85 | I5: =VLOOKUP(A5,'[2]2020'!$A$2:$C$24,3,0) -> 34073.91 | J5: =VLOOKUP(A5,'[2]2020'!$A$2:$E$24,4,0) -> 20418.43 | K5: =VLOOKUP(A5,'[5]2020'!$A$2:$M$24,13,0) -> 276281.09 | L5: =VLOOKUP(A5,'[2]2020'!$A$2:$E$24,5,0) -> 3738.84 | M5: =VLOOKUP(A5,'[3]2020'!$A$2:$O$24,15,0) -> 13444.33 | N5: =VLOOKUP(A5,'[2]2020'!$A$2:$F$24,6,0) -> 217415.4 | O5: =VLOOKUP(A5,'[7]2020'!$A$2:$C$24,3,0) -> 17000 | P5: =VLOOKUP(A5,'[4]2020'!$A$2:$R$24,18,0) -> 7987990.4 | Q5: =VLOOKUP(A5,'[2]2020'!$A$2:$G$24,7,0) -> 131826.5 | R5: =VLOOKUP(A5,'[2]2020'!$A$2:$I$24,8,0) -> 331609.77 | S5: =VLOOKUP(A5,'[2]2020'!$A$2:$I$24,9,0) -> 129317.16 | T5: =SUM(C5:S5) -> 61469019 | U5: =T5/B5 -> 31697.315 | V5: =U5/365 -> 86.841959
A6: 0173EF31312610910 | B6: =VLOOKUP(A6,[8]Ocupação!$E$27:$F$48,2,0) -> 726.08333 | C6: =VLOOKUP(A6,'[1]2020'!$A$1:$D$22,4,0) -> 15060430 | F6: =VLOOKUP(A6,'[3]2020'!$A$2:$H$24,8,0) -> 139116.56 | G6: =VLOOKUP(A6,'[3]2020'!$A$2:$I$24,9,0) -> 13751.49 | H6: =VLOOKUP(A6,'[6]2020'!$A$2:$F$24,6,0) -> 91154.99 | I6: =VLOOKUP(A6,'[2]2020'!$A$2:$C$24,3,0) -> 15529.69 | J6: =VLOOKUP(A6,'[2]2020'!$A$2:$E$24,4,0) -> 14463.85 | K6: =VLOOKUP(A6,'[5]2020'!$A$2:$M$24,13,0) -> 0 | L6: =VLOOKUP(A6,'[2]2020'!$A$2:$E$24,5,0) -> 0 | M6: =VLOOKUP(A6,'[3]2020'!$A$2:$O$24,15,0) -> 6782.72 | N6: =VLOOKUP(A6,'[2]2020'!$A$2:$F$24,6,0) -> 45573.48 | O6: =VLOOKUP(A6,'[7]2020'!$A$2:$C$24,3,0) -> 5000 | P6: =VLOOKUP(A6,'[4]2020'!$A$2:$R$24,18,0) -> 3374423.6 | Q6: =VLOOKUP(A6,'[2]2020'!$A$2:$G$24,7,0) -> 37858.9 | R6: =VLOOKUP(A6,'[2]2020'!$A$2:$I$24,8,0) -> 1381921 | S6: =VLOOKUP(A6,'[2]2020'!$A$2:$I$24,9,0) -> 83100.54 | T6: =SUM(C6:S6) -> 20269107 | U6: =T6/B6 -> 27915.675 | V6: =U6/365 -> 76.481303
A7: 0174EF31312770100 | B7: =VLOOKUP(A7,[8]Ocupação!$E$27:$F$48,2,0) -> 1187.75 | C7: =VLOOKUP(A7,'[1]2020'!$A$1:$D$22,4,0) -> 24483428 | F7: =VLOOKUP(A7,'[3]2020'!$A$2:$H$24,8,0) -> 205516.49 | G7: =VLOOKUP(A7,'[3]2020'!$A$2:$I$24,9,0) -> 25149.13 | H7: =VLOOKUP(A7,'[6]2020'!$A$2:$F$24,6,0) -> 1475680 | I7: =VLOOKUP(A7,'[2]2020'!$A$2:$C$24,3,0) -> 12909.5 | J7: =VLOOKUP(A7,'[2]2020'!$A$2:$E$24,4,0) -> 10875.57 | K7: =VLOOKUP(A7,'[5]2020'!$A$2:$M$24,13,0) -> 498907.53 | L7: =VLOOKUP(A7,'[2]2020'!$A$2:$E$24,5,0) -> 570.32 | M7: =VLOOKUP(A7,'[3]2020'!$A$2:$O$24,15,0) -> 6782.72 | N7: =VLOOKUP(A7,'[2]2020'!$A$2:$F$24,6,0) -> 128693.39 | O7: =VLOOKUP(A7,'[7]2020'!$A$2:$C$24,3,0) -> 18000 | P7: =VLOOKUP(A7,'[4]2020'!$A$2:$R$24,18,0) -> 4572129.7 | Q7: =VLOOKUP(A7,'[2]2020'!$A$2:$G$24,7,0) -> 40754.5 | R7: =VLOOKUP(A7,'[2]2020'!$A$2:$I$24,8,0) -> 280127 | S7: =VLOOKUP(A7,'[2]2020'!$A$2:$I$24,9,0) -> 144765 | T7: =SUM(C7:S7) -> 31904289 | U7: =T7/B7 -> 26861.114 | V7: =U7/365 -> 73.592094
A8: 0175EF31313115800 | B8: =VLOOKUP(A8,[8]Ocupação!$E$27:$F$48,2,0) -> 1250.6667 | C8: =VLOOKUP(A8,'[1]2020'!$A$1:$D$22,4,0) -> 20186944 | F8: =VLOOKUP(A8,'[3]2020'!$A$2:$H$24,8,0) -> 201718.83 | G8: =VLOOKUP(A8,'[3]2020'!$A$2:$I$24,9,0) -> 13246.9 | H8: =VLOOKUP(A8,'[6]2020'!$A$2:$F$24,6,0) -> 452256.59 | I8: =VLOOKUP(A8,'[2]2020'!$A$2:$C$24,3,0) -> 16240.76 | J8: =VLOOKUP(A8,'[2]2020'!$A$2:$E$24,4,0) -> 9414.61 | K8: =VLOOKUP(A8,'[5]2020'!$A$2:$M$24,13,0) -> 0 | L8: =VLOOKUP(A8,'[2]2020'!$A$2:$E$24,5,0) -> 175.16 | M8: =VLOOKUP(A8,'[3]2020'!$A$2:$O$24,15,0) -> 6782.72 | N8: =VLOOKUP(A8,'[2]2020'!$A$2:$F$24,6,0) -> 106231.19 | O8: =VLOOKUP(A8,'[7]2020'!$A$2:$C$24,3,0) -> 12000 | P8: =VLOOKUP(A8,'[4]2020'!$A$2:$R$24,18,0) -> 4798954.1 | Q8: =VLOOKUP(A8,'[2]2020'!$A$2:$G$24,7,0) -> 66541.95 | R8: =VLOOKUP(A8,'[2]2020'!$A$2:$I$24,8,0) -> 326823.23 | S8: =VLOOKUP(A8,'[2]2020'!$A$2:$I$24,9,0) -> 62415.08 | T8: =SUM(C8:S8) -> 26259745 | U8: =T8/B8 -> 20996.598 | V8: =U8/365 -> 57.524926
A9: 0176EF31313670212 | B9: =VLOOKUP(A9,[8]Ocupação!$E$27:$F$48,2,0) -> 546.5 | C9: =VLOOKUP(A9,'[1]2020'!$A$1:$D$22,4,0) -> 25665551 | F9: =VLOOKUP(A9,'[3]2020'!$A$2:$H$24,8,0) -> 5620.71 | G9: =VLOOKUP(A9,'[3]2020'!$A$2:$I$24,9,0) -> 15584.8 | H9: =VLOOKUP(A9,'[6]2020'!$A$2:$F$24,6,0) -> 14041.68 | I9: =VLOOKUP(A9,'[2]2020'!$A$2:$C$24,3,0) -> 16119.36 | J9: =VLOOKUP(A9,'[2]2020'!$A$2:$E$24,4,0) -> 11339.69 | K9: =VLOOKUP(A9,'[5]2020'!$A$2:$M$24,13,0) -> 0 | L9: =VLOOKUP(A9,'[2]2020'!$A$2:$E$24,5,0) -> 1043 | M9: =VLOOKUP(A9,'[3]2020'!$A$2:$O$24,15,0) -> 6661.61 | N9: =VLOOKUP(A9,'[2]2020'!$A$2:$F$24,6,0) -> 224792.88 | O9: =VLOOKUP(A9,'[7]2020'!$A$2:$C$24,3,0) -> 15000 | P9: =VLOOKUP(A9,'[4]2020'!$A$2:$R$24,18,0) -> 2793044 | Q9: =VLOOKUP(A9,'[2]2020'!$A$2:$G$24,7,0) -> 47723.55 | R9: =VLOOKUP(A9,'[2]2020'!$A$2:$I$24,8,0) -> 115588.19 | S9: =VLOOKUP(A9,'[2]2020'!$A$2:$I$24,9,0) -> 90415.71 | T9: =SUM(C9:S9) -> 29022526 | U9: =T9/B9 -> 53106.178 | V9: =U9/365 -> 145.49638
A10: 0177EF31313670202 | B10: =VLOOKUP(A10,[8]Ocupação!$E$27:$F$48,2,0) -> 912.5 | C10: =VLOOKUP(A10,'[1]2020'!$A$1:$D$22,4,0) -> 21323539 | F10: =VLOOKUP(A10,'[3]2020'!$A$2:$H$24,8,0) -> 4374.21 | G10: =VLOOKUP(A10,'[3]2020'!$A$2:$I$24,9,0) -> 9916.08 | H10: =VLOOKUP(A10,'[6]2020'!$A$2:$F$24,6,0) -> 5970.35 | I10: =VLOOKUP(A10,'[2]2020'!$A$2:$C$24,3,0) -> 16236.81 | J10: =VLOOKUP(A10,'[2]2020'!$A$2:$E$24,4,0) -> 3802.14 | K10: =VLOOKUP(A10,'[5]2020'!$A$2:$M$24,13,0) -> 0 | L10: =VLOOKUP(A10,'[2]2020'!$A$2:$E$24,5,0) -> 0 | M10: =VLOOKUP(A10,'[3]2020'!$A$2:$O$24,15,0) -> 6661.61 | N10: =VLOOKUP(A10,'[2]2020'!$A$2:$F$24,6,0) -> 91298.47 | O10: =VLOOKUP(A10,'[7]2020'!$A$2:$C$24,3,0) -> 2000 | P10: =VLOOKUP(A10,'[4]2020'!$A$2:$R$24,18,0) -> 4185807.1 | Q10: =VLOOKUP(A10,'[2]2020'!$A$2:$G$24,7,0) -> 64645.15 | R10: =VLOOKUP(A10,'[2]2020'!$A$2:$I$24,8,0) -> 92652.5 | S10: =VLOOKUP(A10,'[2]2020'!$A$2:$I$24,9,0) -> 139715.41 | T10: =SUM(C10:S10) -> 25946619 | U10: =T10/B10 -> 28434.65 | V10: =U10/365 -> 77.903152
A11: 0178EF31314390610 | B11: =VLOOKUP(A11,[8]Ocupação!$E$27:$F$48,2,0) -> 738.33333 | C11: =VLOOKUP(A11,'[1]2020'!$A$1:$D$22,4,0) -> 16468214 | F11: =VLOOKUP(A11,'[3]2020'!$A$2:$H$24,8,0) -> 1647.59 | G11: =VLOOKUP(A11,'[3]2020'!$A$2:$I$24,9,0) -> 14796.77 | H11: =VLOOKUP(A11,'[6]2020'!$A$2:$F$24,6,0) -> 27694.27 | I11: =VLOOKUP(A11,'[2]2020'!$A$2:$C$24,3,0) -> 15829.11 | J11: =VLOOKUP(A11,'[2]2020'!$A$2:$E$24,4,0) -> 8224.73 | K11: =VLOOKUP(A11,'[5]2020'!$A$2:$M$24,13,0) -> 0 | L11: =VLOOKUP(A11,'[2]2020'!$A$2:$E$24,5,0) -> 0 | M11: =VLOOKUP(A11,'[3]2020'!$A$2:$O$24,15,0) -> 6782.72 | N11: =VLOOKUP(A11,'[2]2020'!$A$2:$F$24,6,0) -> 76354.7 | O11: =VLOOKUP(A11,'[7]2020'!$A$2:$C$24,3,0) -> 16000 | P11: =VLOOKUP(A11,'[4]2020'!$A$2:$R$24,18,0) -> 3431737.7 | Q11: =VLOOKUP(A11,'[2]2020'!$A$2:$G$24,7,0) -> 39757.37 | R11: =VLOOKUP(A11,'[2]2020'!$A$2:$I$24,8,0) -> 152784.59 | S11: =VLOOKUP(A11,'[2]2020'!$A$2:$I$24,9,0) -> 50397.02 | T11: =SUM(C11:S11) -> 20310221 | U11: =T11/B11 -> 27508.2 | V11: =U11/365 -> 75.364932
A12: 0179EF31314710512 | B12: =VLOOKUP(A12,[8]Ocupação!$E$27:$F$48,2,0) -> 813.41667 | C12: =VLOOKUP(A12,'[1]2020'!$A$1:$D$22,4,0) -> 14262090 | F12: =VLOOKUP(A12,'[3]2020'!$A$2:$H$24,8,0) -> 5970.78 | G12: =VLOOKUP(A12,'[3]2020'!$A$2:$I$24,9,0) -> 35470.3 | H12: =VLOOKUP(A12,'[6]2020'!$A$2:$F$24,6,0) -> 193513.52 | I12: =VLOOKUP(A12,'[2]2020'!$A$2:$C$24,3,0) -> 19412.95 | J12: =VLOOKUP(A12,'[2]2020'!$A$2:$E$24,4,0) -> 15368.96 | K12: =VLOOKUP(A12,'[5]2020'!$A$2:$M$24,13,0) -> 0 | L12: =VLOOKUP(A12,'[2]2020'!$A$2:$E$24,5,0) -> 0 | M12: =VLOOKUP(A12,'[3]2020'!$A$2:$O$24,15,0) -> 6782.72 | N12: =VLOOKUP(A12,'[2]2020'!$A$2:$F$24,6,0) -> 20118.08 | O12: =VLOOKUP(A12,'[7]2020'!$A$2:$C$24,3,0) -> 0 | P12: =VLOOKUP(A12,'[4]2020'!$A$2:$R$24,18,0) -> 3474988.4 | Q12: =VLOOKUP(A12,'[2]2020'!$A$2:$G$24,7,0) -> 64444.68 | R12: =VLOOKUP(A12,'[2]2020'!$A$2:$I$24,8,0) -> 112993.31 | S12: =VLOOKUP(A12,'[2]2020'!$A$2:$I$24,9,0) -> 108940.78 | T12: =SUM(C12:S12) -> 18320094 | U12: =T12/B12 -> 22522.398 | V12: =U12/365 -> 61.705201
A13: 0180EF31314810310 | B13: =VLOOKUP(A13,[8]Ocupação!$E$27:$F$48,2,0) -> 1089 | C13: =VLOOKUP(A13,'[1]2020'!$A$1:$D$22,4,0) -> 22805164 | F13: =VLOOKUP(A13,'[3]2020'!$A$2:$H$24,8,0) -> 201542.13 | G13: =VLOOKUP(A13,'[3]2020'!$A$2:$I$24,9,0) -> 16066.34 | H13: =VLOOKUP(A13,'[6]2020'!$A$2:$F$24,6,0) -> 88516.69 | I13: =VLOOKUP(A13,'[2]2020'!$A$2:$C$24,3,0) -> 15558.28 | J13: =VLOOKUP(A13,'[2]2020'!$A$2:$E$24,4,0) -> 11016.82 | K13: =VLOOKUP(A13,'[5]2020'!$A$2:$M$24,13,0) -> 0 | L13: =VLOOKUP(A13,'[2]2020'!$A$2:$E$24,5,0) -> 448.18 | M13: =VLOOKUP(A13,'[3]2020'!$A$2:$O$24,15,0) -> 12835.29 | N13: =VLOOKUP(A13,'[2]2020'!$A$2:$F$24,6,0) -> 103190.85 | O13: =VLOOKUP(A13,'[7]2020'!$A$2:$C$24,3,0) -> 8000 | P13: =VLOOKUP(A13,'[4]2020'!$A$2:$R$24,18,0) -> 4089929.3 | Q13: =VLOOKUP(A13,'[2]2020'!$A$2:$G$24,7,0) -> 49705.88 | R13: =VLOOKUP(A13,'[2]2020'!$A$2:$I$24,8,0) -> 174041.19 | S13: =VLOOKUP(A13,'[2]2020'!$A$2:$I$24,9,0) -> 59387.4 | T13: =SUM(C13:S13) -> 27635402 | U13: =T13/B13 -> 25376.861 | V13: =U13/365 -> 69.525647
A14: 0181EF31315210510 | B14: =VLOOKUP(A14,[8]Ocupação!$E$27:$F$48,2,0) -> 1097.4167 | C14: =VLOOKUP(A14,'[1]2020'!$A$1:$D$22,4,0) -> 16771204 | F14: =VLOOKUP(A14,'[3]2020'!$A$2:$H$24,8,0) -> 207463.39 | G14: =VLOOKUP(A14,'[3]2020'!$A$2:$I$24,9,0) -> 15344.04 | H14: =VLOOKUP(A14,'[6]2020'!$A$2:$F$24,6,0) -> 364507.35 | I14: =VLOOKUP(A14,'[2]2020'!$A$2:$C$24,3,0) -> 18564.2 | J14: =VLOOKUP(A14,'[2]2020'!$A$2:$E$24,4,0) -> 14315.77 | K14: =VLOOKUP(A14,'[5]2020'!$A$2:$M$24,13,0) -> 0 | L14: =VLOOKUP(A14,'[2]2020'!$A$2:$E$24,5,0) -> 0 | M14: =VLOOKUP(A14,'[3]2020'!$A$2:$O$24,15,0) -> 12835.29 | N14: =VLOOKUP(A14,'[2]2020'!$A$2:$F$24,6,0) -> 117491.82 | O14: =VLOOKUP(A14,'[7]2020'!$A$2:$C$24,3,0) -> 12000 | P14: =VLOOKUP(A14,'[4]2020'!$A$2:$R$24,18,0) -> 4267870.9 | Q14: =VLOOKUP(A14,'[2]2020'!$A$2:$G$24,7,0) -> 66309.18 | R14: =VLOOKUP(A14,'[2]2020'!$A$2:$I$24,8,0) -> 142906.17 | S14: =VLOOKUP(A14,'[2]2020'!$A$2:$I$24,9,0) -> 84526.03 | T14: =SUM(C14:S14) -> 22095338 | U14: =T14/B14 -> 20133.955 | V14: =U14/365 -> 55.161521
... A24: 0228EF31315460610 | B24: =VLOOKUP(A24,[8]Ocupação!$E$27:$F$48,2,0) -> 667.33333 | C24: =VLOOKUP(A24,'[1]2020'!$A$1:$D$22,4,0) -> #N/A | F24: =VLOOKUP(A24,'[3]2020'!$A$2:$H$24,8,0) -> NA | G24: =VLOOKUP(A24,'[3]2020'!$A$2:$I$24,9,0) -> NA | H24: =VLOOKUP(A24,'[6]2020'!$A$2:$F$24,6,0) -> 0 | I24: =VLOOKUP(A24,'[2]2020'!$A$2:$C$24,3,0) -> N/A | J24: =VLOOKUP(A24,'[2]2020'!$A$2:$E$24,4,0) -> N/A | K24: =VLOOKUP(A24,'[5]2020'!$A$2:$M$24,13,0) -> 0 | L24: =VLOOKUP(A24,'[2]2020'!$A$2:$E$24,5,0) -> N/A | M24: =VLOOKUP(A24,'[3]2020'!$A$2:$O$24,15,0) -> NA | N24: =VLOOKUP(A24,'[2]2020'!$A$2:$F$24,6,0) -> N/A | O24: =VLOOKUP(A24,'[7]2020'!$A$2:$C$24,3,0) -> 0 | P24: =VLOOKUP(A24,'[4]2020'!$A$2:$R$24,18,0) -> 0 | Q24: =VLOOKUP(A24,'[2]2020'!$A$2:$G$24,7,0) -> N/A | R24: =VLOOKUP(A24,'[2]2020'!$A$2:$I$24,8,0) -> N/A | S24: =VLOOKUP(A24,'[2]2020'!$A$2:$I$24,9,0) -> N/A | T24: =SUM(C24:S24) -> #N/A | U24: =T24/B24 -> #N/A | V24: =U24/365 -> #N/A

Sheet 2021
A1: CHAVE | C1: 1- Salários com a administração penitenciária | D1: 2 - Salários com outras administrações | E1: 3 - Pagamento a prestadores de serviço | F1: 4 - Aluguéis de bens imóveis, móveis, veículos e equipamentos de informática | G1: 5 - Água, luz, internet, telefone, lixo e esgoto | H1: 6 - Transportes e combustíveis | I1: 7 - Material de limpeza | J1: 8 - Material de escritório | K1: 9 - Manutenção predial | L1: 10 - Manutenção de equipamentos de segurança | M1: 11 - Manutenção de equipamentos de informática | N1: 12 - Aquisição de equipamentos de segurança, de informática, veículos, móveis e imóveis | O1: 13 - Atividades laborais e educacionais | P1: 14 - Alimentação | Q1: 15 - Material de higiene pessoal | R1: 16 - Colchões, uniformes, roupas de cama e banho | S1: 17- Recursos para assistência à saúde do preso (médica, odontológica, psicológica, terapia ocupacional, etc.)
A2: 0169MO31310620002 | B2: 3370.5833 | C2: =VLOOKUP(A2,'[1]2021'!$A$1:$D$22,4,0) -> 9771541.3 | F2: =VLOOKUP(A2,'[3]2021'!$A$2:$H$24,8,0) -> 9324.31 | G2: =VLOOKUP(A2,'[3]2021'!$A$2:$I$24,9,0) -> 9286.22 | H2: =VLOOKUP(A2,'[6]2021'!$A$2:$F$24,6,0) -> 8419.87 | I2: =VLOOKUP(A2,'[2]2021'!$A$2:$C$24,3,0) -> 3804.76 | J2: =VLOOKUP(A2,'[2]2021'!$A$2:$E$24,4,0) -> 3268.55 | K2: =VLOOKUP(A2,'[5]2021'!$A$2:$M$24,13,0) -> 0 | L2: =VLOOKUP(A2,'[2]2021'!$A$2:$E$24,5,0) -> 0 | M2: =VLOOKUP(A2,'[3]2021'!$A$2:$O$24,15,0) -> 14872.32 | N2: =VLOOKUP(A2,'[2]2021'!$A$2:$F$24,6,0) -> 84967.54 | O2: =VLOOKUP(A2,'[7]2021'!$A$2:$C$24,3,0) -> 0 | P2: =VLOOKUP(A2,'[4]2021'!$A$2:$R$24,18,0) -> 0 | Q2: =VLOOKUP(A2,'[2]2021'!$A$2:$G$24,7,0) -> 1472.48 | R2: =VLOOKUP(A2,'[2]2021'!$A$2:$I$24,8,0) -> 0 | S2: =VLOOKUP(A2,'[2]2021'!$A$2:$I$24,9,0) -> 0
A3: 0170EF31310620011 | B3: =VLOOKUP(A3,[8]Ocupação!$E$50:$F$71,2,0) -> 368.91667 | C3: =VLOOKUP(A3,'[1]2021'!$A$1:$D$22,4,0) -> 17371360 | F3: =VLOOKUP(A3,'[3]2021'!$A$2:$H$24,8,0) -> 204406.43 | G3: =VLOOKUP(A3,'[3]2021'!$A$2:$I$24,9,0) -> 27757.4 | H3: =VLOOKUP(A3,'[6]2021'!$A$2:$F$24,6,0) -> 30706.46 | I3: =VLOOKUP(A3,'[2]2021'!$A$2:$C$24,3,0) -> 15983.89 | J3: =VLOOKUP(A3,'[2]2021'!$A$2:$E$24,4,0) -> 8257.97 | K3: =VLOOKUP(A3,'[5]2021'!$A$2:$M$24,13,0) -> 265958.18 | L3: =VLOOKUP(A3,'[2]2021'!$A$2:$E$24,5,0) -> 0 | M3: =VLOOKUP(A3,'[3]2021'!$A$2:$O$24,15,0) -> 0 | N3: =VLOOKUP(A3,'[2]2021'!$A$2:$F$24,6,0) -> 85862.85 | O3: =VLOOKUP(A3,'[7]2021'!$A$2:$C$24,3,0) -> 35075.04 | P3: =VLOOKUP(A3,'[4]2021'!$A$2:$R$24,18,0) -> 1729201.6 | Q3: =VLOOKUP(A3,'[2]2021'!$A$2:$G$24,7,0) -> 60598.71 | R3: =VLOOKUP(A3,'[2]2021'!$A$2:$I$24,8,0) -> 78965.17 | S3: =VLOOKUP(A3,'[2]2021'!$A$2:$I$24,9,0) -> 139332.49
A4: 0171EF31311430300 | B4: =VLOOKUP(A4,[8]Ocupação!$E$50:$F$71,2,0) -> 586.08333 | C4: =VLOOKUP(A4,'[1]2021'!$A$1:$D$22,4,0) -> 18208737 | F4: =VLOOKUP(A4,'[3]2021'!$A$2:$H$24,8,0) -> 251328.99 | G4: =VLOOKUP(A4,'[3]2021'!$A$2:$I$24,9,0) -> 15554.77 | H4: =VLOOKUP(A4,'[6]2021'!$A$2:$F$24,6,0) -> 50245.41 | I4: =VLOOKUP(A4,'[2]2021'!$A$2:$C$24,3,0) -> 19494.57 | J4: =VLOOKUP(A4,'[2]2021'!$A$2:$E$24,4,0) -> 6504.99 | K4: =VLOOKUP(A4,'[5]2021'!$A$2:$M$24,13,0) -> 0 | L4: =VLOOKUP(A4,'[2]2021'!$A$2:$E$24,5,0) -> 0 | M4: =VLOOKUP(A4,'[3]2021'!$A$2:$O$24,15,0) -> 6863.16 | N4: =VLOOKUP(A4,'[2]2021'!$A$2:$F$24,6,0) -> 45162.04 | O4: =VLOOKUP(A4,'[7]2021'!$A$2:$C$24,3,0) -> 8000 | P4: =VLOOKUP(A4,'[4]2021'!$A$2:$R$24,18,0) -> 2683840.5 | Q4: =VLOOKUP(A4,'[2]2021'!$A$2:$G$24,7,0) -> 30495.01 | R4: =VLOOKUP(A4,'[2]2021'!$A$2:$I$24,8,0) -> 50766.75 | S4: =VLOOKUP(A4,'[2]2021'!$A$2:$I$24,9,0) -> 53697.36
A5: 0172EF31311860112 | B5: =VLOOKUP(A5,[8]Ocupação!$E$50:$F$71,2,0) -> 2332.75 | C5: =VLOOKUP(A5,'[1]2021'!$A$1:$D$22,4,0) -> 59785260 | F5: =VLOOKUP(A5,'[3]2021'!$A$2:$H$24,8,0) -> 259100.53 | G5: =VLOOKUP(A5,'[3]2021'!$A$2:$I$24,9,0) -> 14549.64 | H5: =VLOOKUP(A5,'[6]2021'!$A$2:$F$24,6,0) -> 480358.08 | I5: =VLOOKUP(A5,'[2]2021'!$A$2:$C$24,3,0) -> 38091.96 | J5: =VLOOKUP(A5,'[2]2021'!$A$2:$E$24,4,0) -> 19187.48 | K5: =VLOOKUP(A5,'[5]2021'!$A$2:$M$24,13,0) -> 248954.94 | L5: =VLOOKUP(A5,'[2]2021'!$A$2:$E$24,5,0) -> 333.99 | M5: =VLOOKUP(A5,'[3]2021'!$A$2:$O$24,15,0) -> 14739.6 | N5: =VLOOKUP(A5,'[2]2021'!$A$2:$F$24,6,0) -> 81469.66 | O5: =VLOOKUP(A5,'[7]2021'!$A$2:$C$24,3,0) -> 68021.96 | P5: =VLOOKUP(A5,'[4]2021'!$A$2:$R$24,18,0) -> 10698442 | Q5: =VLOOKUP(A5,'[2]2021'!$A$2:$G$24,7,0) -> 181089.42 | R5: =VLOOKUP(A5,'[2]2021'!$A$2:$I$24,8,0) -> 304859.6 | S5: =VLOOKUP(A5,'[2]2021'!$A$2:$I$24,9,0) -> 149746.48
A6: 0173EF31312610910 | B6: =VLOOKUP(A6,[8]Ocupação!$E$50:$F$71,2,0) -> 661.25 | C6: =VLOOKUP(A6,'[1]2021'!$A$1:$D$22,4,0) -> 19869635 | F6: =VLOOKUP(A6,'[3]2021'!$A$2:$H$24,8,0) -> 253402.33 | G6: =VLOOKUP(A6,'[3]2021'!$A$2:$I$24,9,0) -> 27526.74 | H6: =VLOOKUP(A6,'[6]2021'!$A$2:$F$24,6,0) -> 76315.46 | I6: =VLOOKUP(A6,'[2]2021'!$A$2:$C$24,3,0) -> 15864.28 | J6: =VLOOKUP(A6,'[2]2021'!$A$2:$E$24,4,0) -> 7961.08 | K6: =VLOOKUP(A6,'[5]2021'!$A$2:$M$24,13,0) -> 0 | L6: =VLOOKUP(A6,'[2]2021'!$A$2:$E$24,5,0) -> 0 | M6: =VLOOKUP(A6,'[3]2021'!$A$2:$O$24,15,0) -> 6863.16 | N6: =VLOOKUP(A6,'[2]2021'!$A$2:$F$24,6,0) -> 104977.65 | O6: =VLOOKUP(A6,'[7]2021'!$A$2:$C$24,3,0) -> 7499.98 | P6: =VLOOKUP(A6,'[4]2021'!$A$2:$R$24,18,0) -> 3381091.9 | Q6: =VLOOKUP(A6,'[2]2021'!$A$2:$G$24,7,0) -> 29454.81 | R6: =VLOOKUP(A6,'[2]2021'!$A$2:$I$24,8,0) -> 271998.11 | S6: =VLOOKUP(A6,'[2]2021'!$A$2:$I$24,9,0) -> 117298.01
A7: 0174EF31312770100 | B7: =VLOOKUP(A7,[8]Ocupação!$E$50:$F$71,2,0) -> 1234.6667 | C7: =VLOOKUP(A7,'[1]2021'!$A$1:$D$22,4,0) -> 29683945 | F7: =VLOOKUP(A7,'[3]2021'!$A$2:$H$24,8,0) -> 204431.82 | G7: =VLOOKUP(A7,'[3]2021'!$A$2:$I$24,9,0) -> 51592.22 | H7: =VLOOKUP(A7,'[6]2021'!$A$2:$F$24,6,0) -> 1158145.2 | I7: =VLOOKUP(A7,'[2]2021'!$A$2:$C$24,3,0) -> 12125.96 | J7: =VLOOKUP(A7,'[2]2021'!$A$2:$E$24,4,0) -> 6559.67 | K7: =VLOOKUP(A7,'[5]2021'!$A$2:$M$24,13,0) -> 0 | L7: =VLOOKUP(A7,'[2]2021'!$A$2:$E$24,5,0) -> 0 | M7: =VLOOKUP(A7,'[3]2021'!$A$2:$O$24,15,0) -> 6863.16 | N7: =VLOOKUP(A7,'[2]2021'!$A$2:$F$24,6,0) -> 41023.82 | O7: =VLOOKUP(A7,'[7]2021'!$A$2:$C$24,3,0) -> 22499.98 | P7: =VLOOKUP(A7,'[4]2021'!$A$2:$R$24,18,0) -> 4723929.9 | Q7: =VLOOKUP(A7,'[2]2021'!$A$2:$G$24,7,0) -> 43943.35 | R7: =VLOOKUP(A7,'[2]2021'!$A$2:$I$24,8,0) -> 241878.48 | S7: =VLOOKUP(A7,'[2]2021'!$A$2:$I$24,9,0) -> 116160.12
A8: 0175EF31313115800 | B8: =VLOOKUP(A8,[8]Ocupação!$E$50:$F$71,2,0) -> 1221.1667 | C8: =VLOOKUP(A8,'[1]2021'!$A$1:$D$22,4,0) -> 27484734 | F8: =VLOOKUP(A8,'[3]2021'!$A$2:$H$24,8,0) -> 203829.55 | G8: =VLOOKUP(A8,'[3]2021'!$A$2:$I$24,9,0) -> 29639.92 | H8: =VLOOKUP(A8,'[6]2021'!$A$2:$F$24,6,0) -> 458083.53 | I8: =VLOOKUP(A8,'[2]2021'!$A$2:$C$24,3,0) -> 16779.69 | J8: =VLOOKUP(A8,'[2]2021'!$A$2:$E$24,4,0) -> 7618.24 | K8: =VLOOKUP(A8,'[5]2021'!$A$2:$M$24,13,0) -> 0 | L8: =VLOOKUP(A8,'[2]2021'!$A$2:$E$24,5,0) -> 492.59 | M8: =VLOOKUP(A8,'[3]2021'!$A$2:$O$24,15,0) -> 619.68 | N8: =VLOOKUP(A8,'[2]2021'!$A$2:$F$24,6,0) -> 92738.62 | O8: =VLOOKUP(A8,'[7]2021'!$A$2:$C$24,3,0) -> 12000 | P8: =VLOOKUP(A8,'[4]2021'!$A$2:$R$24,18,0) -> 5670083 | Q8: =VLOOKUP(A8,'[2]2021'!$A$2:$G$24,7,0) -> 57443.65 | R8: =VLOOKUP(A8,'[2]2021'!$A$2:$I$24,8,0) -> 291430.41 | S8: =VLOOKUP(A8,'[2]2021'!$A$2:$I$24,9,0) -> 51041.52
A9: 0176EF31313670212 | B9: =VLOOKUP(A9,[8]Ocupação!$E$50:$F$71,2,0) -> 1045.3333 | C9: =VLOOKUP(A9,'[1]2021'!$A$1:$D$22,4,0) -> 38252135 | F9: =VLOOKUP(A9,'[3]2021'!$A$2:$H$24,8,0) -> 8026.88 | G9: =VLOOKUP(A9,'[3]2021'!$A$2:$I$24,9,0) -> 41115.6 | H9: =VLOOKUP(A9,'[6]2021'!$A$2:$F$24,6,0) -> 8169.88 | I9: =VLOOKUP(A9,'[2]2021'!$A$2:$C$24,3,0) -> 18387.06 | J9: =VLOOKUP(A9,'[2]2021'!$A$2:$E$24,4,0) -> 8871.17 | K9: =VLOOKUP(A9,'[5]2021'!$A$2:$M$24,13,0) -> 0 | L9: =VLOOKUP(A9,'[2]2021'!$A$2:$E$24,5,0) -> 0 | M9: =VLOOKUP(A9,'[3]2021'!$A$2:$O$24,15,0) -> 6740.64 | N9: =VLOOKUP(A9,'[2]2021'!$A$2:$F$24,6,0) -> 305304.28 | O9: =VLOOKUP(A9,'[7]2021'!$A$2:$C$24,3,0) -> 15000 | P9: =VLOOKUP(A9,'[4]2021'!$A$2:$R$24,18,0) -> 4794557.7 | Q9: =VLOOKUP(A9,'[2]2021'!$A$2:$G$24,7,0) -> 102012.97 | R9: =VLOOKUP(A9,'[2]2021'!$A$2:$I$24,8,0) -> 200976.64 | S9: =VLOOKUP(A9,'[2]2021'!$A$2:$I$24,9,0) -> 92352.92
